Workbook

Sheet ENERO
D1: PUESTOS DE VACUNACIÓN ACTIVOS | O1: PUESTOS DE VACUNACIÓN QUE NOTIFICARON | Z1: PORCENTAJE DE PUESTOS DE VACUNACIÓN NOTIFICANTES | KH1: POBLACIÓN INDÍGENA | KM1: POBLACIÓN INDÍGENA | KR1: POBLACIÓN INDÍGENA
D2: CP1 | E2: CP2 | F2: CP3 | G2: HOSPITAL | H2: CDI | I2: IVSS | J2: I.P.A.S.M.E | K2: SANIDAD MILITAR | L2: PRIVADO | M2: OTROS | N2: N° PUESTOS DE VACUNACIÓN ACTIVOS | O2: CP1 | P2: CP2 | Q2: CP3 | R2: HOSPITAL | S2: CDI | T2: IVSS | U2: I.P.A.S.M.E | V2: SANIDAD MILITAR | W2: PRIVADO | X2: OTROS | Y2: N° PUESTOS DE VACUNACIÓN NOTIFICANTES | Z2: CP1 | AA2: CP2 | AB2: CP3 | AC2: HOSPITAL | AD2: CDI | AE2: IVSS | AF2: I.P.A.S.M.E | AG2: SANIDAD MILITAR | AH2: PRIVADO | AI2: OTROS | AJ2: % PUESTOS DE VACUNACIÓN NOTIFICANTES | AK2: NACIDOS VIVOS REPORTADOS | AL2: BCG | AU2: HEPATITIS B | BA2: HEPATITIS B | BE2: HEPATITIS B | BI2: HEPATITIS B | BM2: HEPATITIS B | BQ2: HEPATITIS B | BV2: ROTAVIRUS | BZ2: PENTA VALENTE | CC2: PENTA VALENTE | CG2: PENTA VALENTE | CK2: PENTA VALENTE | CO2: PENTA VALENTE | CS2: PENTA VALENTE | CX2: PENTA VALENTE | DD2: POLIO INACTIVA | DG2: POLIO ORAL | DI2: POLIO | DN2: POLIO | DS2: POLIO | DX2: POLIO | EC2: POLIO | EL2: NEUMOCOCO CONJUGADA | EP2: INFLUENZA ESTACIONAL | EZ2: FIEBRE AMARILLA | FI2: SRP | FT2: SR | GJ2: SRP / SR | GQ2: TOTAL | GR2: VPH | GT2: TOXOIDE TETÁNICO DIFTÉRICO | HD2: TOXOIDE TETÁNICO DIFTÉRICO | HM2: TOXOIDE TETÁNICO DIFTÉRICO | HT2: NEUMOCOCO POLISACARIDA | HW2: MENINGOCÓCICA B-C | ID2: RABIA HUMANA | IO2: TOTAL DOSIS ADMINISTRADAS | IP2: PERSONAS VACUNADAS SEGÚN GRUPO DE EDAD Y SEXO | JD2: TOTAL POR SEXO | JF2: TOTAL PERSONAS VACUNADAS SEGÚN GRUPO DE EDAD Y SEXO | JG2: VIAJEROS INTERNACIONALES VACUNADOS SEGÚN BIOLÓGICO | JL2: TOTAL DE VIAJEROS INTERNACINNALES VACUNADOS SEGÚN BIOLÓGICO | JM2: CERTIFICADOS DE FIEBRE AMARILLA | JO2: TOTAL DE CERTIFICADOS INTERNACIONALES | JP2: DOSIS PERDIDAS | KG2: TOTAL DOSIS PERDIDAS | KH2: BCG | KI2: HEPATITIS B | KJ2: HEPATITIS B (Ped) | KK2: ROTAVIRUS | KL2: PENTA VALENTE | KM2: POLIO INACTIVA | KN2: POLIO ORAL | KO2: NEUMOCOCO CONJUGADA | KP2: INFLUENZA ESTACIONAL | KQ2: FIEBRE AMARILLA | KR2: SRP | KS2: SR | KT2: TOXOIDE TETÁNICO DIFTÉRICO | KU2: NEUMOCOCO POLISACÁRIDA | KV2: MENINGOCÓCICA B-C | KW2: RABIA HUMANA | KX2: VPH | KY2: TOTAL DOSIS ADMINISTRADAS | KZ2: TOTAL PERSONAS VACUNADAS (POBLACIÓN INDIGENA) | LA2: SUERO ANTIRRÁBICO HUMANO | LM2: SUERO ANTIOFÍDICO POLIVALENTE | LR2: SUERO ANTITETÁNICO | LX2: SUERO ANTIESCORPIÓNICO | MB2: ANTITOXINA DIFTÉRICA | ME2: SUERO ANTIHEPATITIS B | MI2: PPD
AT3: TOTAL | AU3: HEPATITIS B (PEDIATRICA) | AW3: PERSONAL DE SALUD | BA3: PACIENTES EN DIÁLISIS | BE3: PRIVADOS DE LIBERTAD | BI3: TRABAJADORES SEXUALES | BM3: EMBARAZADAS | BU3: TOTAL | BY3: TOTAL | DC3: TOTAL | DF3: TOTAL | DI3: 1 A. | DN3: 2 A. | DS3: 3 A. | DX3: 4 A. | EC3: 5 A. | EI3: IPV | EJ3: TOTAL IPV | EK3: TOTAL bOPV | EO3: TOTAL | ET3: E. CRÓNICOS | EU3: PERS. SALUD | EV3: EMBARAZADAS | EW3: A. MAYORES | EX3: PER. ESENCIAL | EY3: TOTAL | FH3: TOTAL | FS3: TOTAL | FT3: DOSIS PLAN NACIONAL DE VACUNACIÓN | GR3: FEMENINAS | GS3: TOTAL | GV3: ESCOLARES | GX3: MUJERES EN EDAD FERTIL | HD3: EMBARAZADAS | HG3: HOMBRES | HS3: TOTAL | HT3: ADULTOS MAYORES | HV3: TOTAL | HW3: PERSONAL DE SALUD | HY3: CONTINGENTES MILITARES | IA3: CONTENCIÓN DE BROTES | IC3: TOTAL | IN3: TOTAL | JP3: BCG | JQ3: HEPATITIS B | JR3: HEPATITIS B (Ped) | JS3: ROTAVIRUS | JT3: PENTA VALENTE | JU3: POLIO INACTIVA | JV3: POLIO ORAL | JW3: NEUMOCOCO 13 VALENTE | JX3: INFLUENZA ESTACIONAL | JY3: FIEBRE AMARILLA | JZ3: SRP | KA3: SR | KB3: TOXOIDE TETÁNICO DIFTÉRICO | KC3: NEUMOCOCO23 VALENTE | KD3: MENINGOCÓCICA B-C | KE3: RABIA HUMANA | KF3: VPH | LA3: N° PERSONAS MORDIDAS | LB3: N° PERSONAS TRATADAS | LC3: N° PERSONAS HOSPITALIZADAS | LD3: N° PERSONAS CON TRATAMIENTO AMBULATORIO | LE3: N° TRATAMIENTOS ADMINISTRADOS | LI3: N° AMPOLLAS DE SUEROS ADMINISTRADOS | LM3: N° PERSONAS MORDIDAS | LN3: N° PERSONAS HOSPITALIZADAS | LO3: N° PERSONAS CON TRATAMIENTO AMBULATORIO | LP3: N° TRATAMIENTOS ADMINISTRADOS | LQ3: N° VIALES ADMINISTRADOS | LR3: N° CASOS DE TÉTANOS REPORTADOS | LS3: N° PERSONAS HOSPITALIZADAS | LT3: N° PERSONAS CON TRATAMIENTO AMBULATORIO | LU3: N° AMPOLLAS ADMINISTRADAS | LX3: N° EMPONZOÑAMIENTOS | LY3: N° PERSONAS HOSPITALIZADAS | LZ3: N° PERSONAS CON TRATAMIENTO AMBULATORIO | MA3: N° AMPOLLAS ADMINISTRADAS | MB3: N° AMPOLLAS ADMINISTRADAS | MC3: N° PERSONAS HOSPITALIZADAS | MD3: N° PERSONAS CON TRATAMIENTO AMBULATORIO | ME3: N° CASOS SOSPECHOSOS | MF3: N° AMPOLLAS ADMINISTRADAS | MG3: N° PERSONAS HOSPITALIZADA | MH3: N° PERSONAS CON TRATAMIENTO AMBULATORIO | MI3: N° CASOS SOSPECHOSOS | MJ3: N° PERSONAS HOSPITALIZADAS | MK3: N° PERSONAS CON TRATAMIENTO AMBULATORIO | ML3: N° DOSIS ADMINISTRADAS | MM3: N° LECTURAS POSITIVAS
AL4: < 28 D. | AM4: ≥ 28 D. - 11 M. | AN4: 1 A. | AO4: 2 A. | AP4: 3 A. | AQ4: 4 A. | AR4: 5 A. | AS4: 6 - 7 A. | AU4: ≤ 24 H. | AV4: 1 - 7 D. | BQ4: 6 - 49 A. | BV4: < 1 A. | BZ4: < 1 A. | CC4: 1 A. | CG4: 2 A. | CK4: 3 A. | CO4: 4 A. | CS4: 5 A. | CX4: 6 A. | DD4: < 1A. | DG4: < 1A. | DI4: POLIO INACTIVA | DK4: POLIO ORAL | DN4: POLIO INACTIVA | DP4: POLIO ORAL | DS4: POLIO INACTIVA | DU4: POLIO ORAL | DX4: POLIO INACTIVA | DZ4: POLIO ORAL | EC4: POLIO INACTIVA | EE4: POLIO ORAL | EI4: 6 A 8 AÑOS | EL4: < 1 A. | EN4: 1 A. | EP4: 6 - 11 M. | ER4: 1 A. | EW4: ≥ 60A. | EZ4: 1 A. | FA4: 2 A. | FB4: 3 A. | FC4: 4 A. | FD4: 5 A. | FE4: 6 - 9 A. | FF4: 10 - 14 A. | FG4: 15 - 59 A. | FI4: 1 A. | FK4: 2 A. | FM4: 3 A. | FO4: 4 A. | FQ4: 5 A. | FT4: 6-11 M. | FU4: 1AÑO | FX4: 2AÑOS | GA4: 3 AÑOS | GD4: 4 AÑOS | GG4: 5 AÑOS | GJ4: 6 A. | GM4: 7 - 9 A. | GN4: 10 A. | GO4: 11 - 15 A. | GP4: 16 - 29 A. | GR4: 10 A. | GT4: 7 - 9 A. | GV4: 10 A. FEME. | GW4: 10 A. MASC. | GX4: 11 - 49 A. | HG4: 11 - 49 A. | HM4: ≥ 50 A. | HT4: ≥ 60 A. | ID4: PRE EXPOSICIÓN | IG4: POST EXPOSICIÓN | IP4: < 1A. | IR4: 1 A. | IT4: 2 A. | IV4: 3 A. | IX4: 4 A. | IZ4: 5 A. | JB4: ≥ 6 A. | JG4: POLIO INAC. | JH4: FIEBRE AMARILLA | JI4: SRP / SR | JJ4: TOXOIDE | JK4: MENING. B-C | JM4: CERTIFICADOS ELABORADOS | JN4: CERTIFICADOS ANULADOS | LE4: COMPLETOS | LG4: INCOMPLETOS
AL5: DU | AM5: DU | AS5: DU | AU5: DU | AV5: DU | AW5: 1D | AX5: 2D | AY5: 3D | AZ5: DA | BA5: 1D | BB5: 2D | BC5: 3D | BD5: DA | BE5: 1D | BF5: 2D | BG5: 3D | BH5: DA | BI5: 1D | BJ5: 2D | BK5: 3D | BL5: DA | BM5: 1D | BN5: 2D | BO5: 3D | BP5: DA | BQ5: 1D | BR5: 2D | BS5: 3D | BT5: DA | BV5: 1D | BW5: 2D | BX5: 3D | BZ5: 1D | CA5: 2D | CB5: 3D | CC5: 1D | CD5: 2D | CE5: 3D | CF5: 1REF | CG5: 1D | CH5: 2D | CI5: 3D | CJ5: 1REF | CK5: 1D | CL5: 2D | CM5: 3D | CN5: 1REF | CO5: 1D | CP5: 2D | CQ5: 3D | CR5: 1REF | CS5: 1D | CT5: 2D | CU5: 3D | CV5: 1REF | CW5: 2REF | CX5: 1D | CY5: 2D | CZ5: 3D | DA5: 1REF | DB5: 2REF | DD5: 1D | DE5: 2D | DG5: 3D | DH5: DA | DI5: 1D | DJ5: 2D | DK5: 3D | DL5: 1REF | DM5: DA | DN5: 1D | DO5: 2D | DP5: 3D | DQ5: 1REF | DR5: DA | DS5: 1D | DT5: 2D | DU5: 3D | DV5: 1REF | DW5: DA | DX5: 1D | DY5: 2D | DZ5: 3D | EA5: 1REF | EB5: DA | EC5: 1D | ED5: 2D | EE5: 3D | EF5: 1REF | EG5: 2REF | EH5: DA | EI5: DA | EL5: 1D | EM5: 2D | EN5: 1REF | EP5: 1D | EQ5: 2D | ER5: 1D | ES5: 2D | ET5: DE | EU5: DE | EV5: DE | EW5: DE | EX5: DE | EZ5: DU | FA5: DU | FB5: DU | FC5: DU | FD5: DU | FE5: DU | FF5: DU | FG5: DU | FI5: 1D | FJ5: 2D | FK5: 1D | FL5: 2D | FM5: 1D | FN5: 2D | FO5: 1D | FP5: 2D | FQ5: 1D | FR5: 2D | FT5: DA | FU5: 1D | FV5: 2D | FW5: DA | FX5: 1D | FY5: 2D | FZ5: DA | GA5: 1D | GB5: 2D | GC5: DA | GD5: 1D | GE5: 2D | GF5: DA | GG5: 1D | GH5: 2D | GI5: DA | GJ5: 1D | GK5: 2D | GL5: DA | GM5: DA | GN5: DA | GO5: DA | GP5: DA | GR5: 1D | GT5: 1D | GU5: 2D | GV5: REF | GW5: REF | GX5: 1D | GY5: 2D | GZ5: 3D | HA5: 4D | HB5: 5D | HC5: DA | HD5: 1D | HE5: 2D | HF5: DA | HG5: 1D | HH5: 2D | HI5: 3D | HJ5: 4D | HK5: 5D | HL5: DA | HM5: 1D | HN5: 2D | HO5: 3D | HP5: 4D | HQ5: 5D | HR5: DA | HT5: 1D | HU5: 1REF | HW5: 1D | HX5: 2D | HY5: 1D | HZ5: 2D | IA5: 1D | IB5: 2D | ID5: 1D | IE5: 2D | IF5: 1REF | IG5: 1D | IH5: 2D | II5: 3D | IJ5: 4D | IK5: 5D | IL5: 6D | IM5: 7D | IP5: M | IQ5: F | IR5: M | IS5: F | IT5: M | IU5: F | IV5: M | IW5: F | IX5: M | IY5: F | IZ5: M | JA5: F | JB5: M | JC5: F | JD5: M | JE5: F | LE5: CON SUERO | LF5: SIN SUERO | LG5: NORMA E. | LH5: ABANDONO | LI5: 1.500 UI | LJ5: 1.000 UI | LK5: 500 UI | LL5: 300 UI | LU5: 1.500 UI | LV5: 3.000 UI | LW5: Ig ANTITETÁNICA
A6: E | B6: 30000 | C6: ANZOÁTEGUI | D6: =SUM(D7,D10,D13,D20,D23,D27,D30,D34,D37,D40,D44,D47,D50,D53,D56,D61,D65,D68,D70,D73,D79) -> 0 | E6: =SUM(E7,E10,E13,E20,E23,E27,E30,E34,E37,E40,E44,E47,E50,E53,E56,E61,E65,E68,E70,E73,E79) -> 4 | F6: =SUM(F7,F10,F13,F20,F23,F27,F30,F34,F37,F40,F44,F47,F50,F53,F56,F61,F65,F68,F70,F73,F79) -> 2 | G6: =SUM(G7,G10,G13,G20,G23,G27,G30,G34,G37,G40,G44,G47,G50,G53,G56,G61,G65,G68,G70,G73,G79) -> 0 | H6: =SUM(H7,H10,H13,H20,H23,H27,H30,H34,H37,H40,H44,H47,H50,H53,H56,H61,H65,H68,H70,H73,H79) -> 1 | I6: =SUM(I7,I10,I13,I20,I23,I27,I30,I34,I37,I40,I44,I47,I50,I53,I56,I61,I65,I68,I70,I73,I79) -> 0 | J6: =SUM(J7,J10,J13,J20,J23,J27,J30,J34,J37,J40,J44,J47,J50,J53,J56,J61,J65,J68,J70,J73,J79) -> 0 | K6: =SUM(K7,K10,K13,K20,K23,K27,K30,K34,K37,K40,K44,K47,K50,K53,K56,K61,K65,K68,K70,K73,K79) -> 0 | ... Y6: =SUM(Y7,Y10,Y13,Y20,Y23,Y27,Y30,Y34,Y37,Y40,Y44,Y47,Y50,Y53,Y56,Y61,Y65,Y68,Y70,Y73,Y79) -> 8 | Z6: =IFERROR(O6/D6,0) -> 0 | AA6: =IFERROR(P6/E6,0) -> 1 | AB6: =IFERROR(Q6/F6,0) -> 1 | AC6: =IFERROR(R6/G6,0) -> 0 | AD6: =IFERROR(S6/H6,0) -> 1 | AE6: =IFERROR(T6/I6,0) -> 0 | AF6: =IFERROR(U6/J6,0) -> 0 | AG6: =IFERROR(V6/K6,0) -> 0 | ... AJ6: =IFERROR(Y6/N6,0) -> 1 | AK6: =SUM(AK7,AK10,AK13,AK20,AK23,AK27,AK30,AK34,AK37,AK40,AK44,AK47,AK50,AK53,AK56,AK61,AK65,AK68,AK70,AK73,AK79) -> 0 | AL6: =SUM(AL7,AL10,AL13,AL20,AL23,AL27,AL30,AL34,AL37,AL40,AL44,AL47,AL50,AL53,AL56,AL61,AL65,AL68,AL70,AL73,AL79) -> 10 | AM6: =SUM(AM7,AM10,AM13,AM20,AM23,AM27,AM30,AM34,AM37,AM40,AM44,AM47,AM50,AM53,AM56,AM61,AM65,AM68,AM70,AM73,AM79) -> 9 | AN6: =SUM(AN7,AN10,AN13,AN20,AN23,AN27,AN30,AN34,AN37,AN40,AN44,AN47,AN50,AN53,AN56,AN61,AN65,AN68,AN70,AN73,AN79) -> 0 | AO6: =SUM(AO7,AO10,AO13,AO20,AO23,AO27,AO30,AO34,AO37,AO40,AO44,AO47,AO50,AO53,AO56,AO61,AO65,AO68,AO70,AO73,AO79) -> 0 | AP6: =SUM(AP7,AP10,AP13,AP20,AP23,AP27,AP30,AP34,AP37,AP40,AP44,AP47,AP50,AP53,AP56,AP61,AP65,AP68,AP70,AP73,AP79) -> 0 | AQ6: =SUM(AQ7,AQ10,AQ13,AQ20,AQ23,AQ27,AQ30,AQ34,AQ37,AQ40,AQ44,AQ47,AQ50,AQ53,AQ56,AQ61,AQ65,AQ68,AQ70,AQ73,AQ79) -> 0 | AR6: =SUM(AR7,AR10,AR13,AR20,AR23,AR27,AR30,AR34,AR37,AR40,AR44,AR47,AR50,AR53,AR56,AR61,AR65,AR68,AR70,AR73,AR79) -> 0 | ... EX6: =SUM(EX7,EX10,EX13,EX20,EX23,EX27,EX30,EX34,EX37,EX40,EX44,EX47,EX50,EX53,EX56,EX61,EX65,EX68,EX70,EX73,EX79) -> 0 | EY6: =SUM(EP6:EX6) -> 0 | EZ6: =SUM(EZ7,EZ10,EZ13,EZ20,EZ23,EZ27,EZ30,EZ34,EZ37,EZ40,EZ44,EZ47,EZ50,EZ53,EZ56,EZ61,EZ65,EZ68,EZ70,EZ73,EZ79) -> 57 | FA6: =SUM(FA7,FA10,FA13,FA20,FA23,FA27,FA30,FA34,FA37,FA40,FA44,FA47,FA50,FA53,FA56,FA61,FA65,FA68,FA70,FA73,FA79) -> 8 | FB6: =SUM(FB7,FB10,FB13,FB20,FB23,FB27,FB30,FB34,FB37,FB40,FB44,FB47,FB50,FB53,FB56,FB61,FB65,FB68,FB70,FB73,FB79) -> 7 | FC6: =SUM(FC7,FC10,FC13,FC20,FC23,FC27,FC30,FC34,FC37,FC40,FC44,FC47,FC50,FC53,FC56,FC61,FC65,FC68,FC70,FC73,FC79) -> 2 | FD6: =SUM(FD7,FD10,FD13,FD20,FD23,FD27,FD30,FD34,FD37,FD40,FD44,FD47,FD50,FD53,FD56,FD61,FD65,FD68,FD70,FD73,FD79) -> 0 | FE6: =SUM(FE7,FE10,FE13,FE20,FE23,FE27,FE30,FE34,FE37,FE40,FE44,FE47,FE50,FE53,FE56,FE61,FE65,FE68,FE70,FE73,FE79) -> 2 | FF6: =SUM(FF7,FF10,FF13,FF20,FF23,FF27,FF30,FF34,FF37,FF40,FF44,FF47,FF50,FF53,FF56,FF61,FF65,FF68,FF70,FF73,FF79) -> 1 | FG6: =SUM(FG7,FG10,FG13,FG20,FG23,FG27,FG30,FG34,FG37,FG40,FG44,FG47,FG50,FG53,FG56,FG61,FG65,FG68,FG70,FG73,FG79) -> 27 | ... GP6: =SUM(GP7,GP10,GP13,GP20,GP23,GP27,GP30,GP34,GP37,GP40,GP44,GP47,GP50,GP53,GP56,GP61,GP65,GP68,GP70,GP73,GP79) -> 0 | GQ6: =SUM(FT6:GP6) -> 0 | GR6: =SUM(GR7,GR10,GR13,GR20,GR23,GR27,GR30,GR34,GR37,GR40,GR44,GR47,GR50,GR53,GR56,GR61,GR65,GR68,GR70,GR73,GR79) -> 0 | GS6: =SUM(GS7,GS10,GS13,GS20,GS23,GS27,GS30,GS34,GS37,GS40,GS44,GS47,GS50,GS53,GS56,GS61,GS65,GS68,GS70,GS73,GS79) -> 0 | GT6: =SUM(GT7,GT10,GT13,GT20,GT23,GT27,GT30,GT34,GT37,GT40,GT44,GT47,GT50,GT53,GT56,GT61,GT65,GT68,GT70,GT73,GT79) -> 0 | GU6: =SUM(GU7,GU10,GU13,GU20,GU23,GU27,GU30,GU34,GU37,GU40,GU44,GU47,GU50,GU53,GU56,GU61,GU65,GU68,GU70,GU73,GU79) -> 0 | GV6: =SUM(GV7,GV10,GV13,GV20,GV23,GV27,GV30,GV34,GV37,GV40,GV44,GV47,GV50,GV53,GV56,GV61,GV65,GV68,GV70,GV73,GV79) -> 28 | GW6: =SUM(GW7,GW10,GW13,GW20,GW23,GW27,GW30,GW34,GW37,GW40,GW44,GW47,GW50,GW53,GW56,GW61,GW65,GW68,GW70,GW73,GW79) -> 15 | GX6: =SUM(GX7,GX10,GX13,GX20,GX23,GX27,GX30,GX34,GX37,GX40,GX44,GX47,GX50,GX53,GX56,GX61,GX65,GX68,GX70,GX73,GX79) -> 68 | GY6: =SUM(GY7,GY10,GY13,GY20,GY23,GY27,GY30,GY34,GY37,GY40,GY44,GY47,GY50,GY53,GY56,GY61,GY65,GY68,GY70,GY73,GY79) -> 19 | ... MM6: =SUM(MM7,MM10,MM13,MM20,MM23,MM27,MM30,MM34,MM37,MM40,MM44,MM47,MM50,MM53,MM56,MM61,MM65,MM68,MM70,MM73,MM79) -> 0
A7: M | B7: 30800 | C7: Municipio Juan Antonio Sotillo | D7: =SUM(D8:D9) -> 0 | E7: =SUM(E8:E9) -> 0 | F7: =SUM(F8:F9) -> 0 | G7: =SUM(G8:G9) -> 0 | H7: =SUM(H8:H9) -> 0 | I7: =SUM(I8:I9) -> 0 | J7: =SUM(J8:J9) -> 0 | K7: =SUM(K8:K9) -> 0 | ... Y7: =SUM(Y8:Y9) -> 0 | Z7: =IFERROR(O7/D7,0) -> 0 | AA7: =IFERROR(P7/E7,0) -> 0 | AB7: =IFERROR(Q7/F7,0) -> 0 | AC7: =IFERROR(R7/G7,0) -> 0 | AD7: =IFERROR(S7/H7,0) -> 0 | AE7: =IFERROR(T7/I7,0) -> 0 | AF7: =IFERROR(U7/J7,0) -> 0 | AG7: =IFERROR(V7/K7,0) -> 0 | ... AJ7: =IFERROR(Y7/N7,0) -> 0 | AK7: =SUM(AK8:AK9) -> 0 | AL7: =SUM(AL8:AL9) -> 0 | AM7: =SUM(AM8:AM9) -> 0 | AN7: =SUM(AN8:AN9) -> 0 | AO7: =SUM(AO8:AO9) -> 0 | AP7: =SUM(AP8:AP9) -> 0 | AQ7: =SUM(AQ8:AQ9) -> 0 | AR7: =SUM(AR8:AR9) -> 0 | ... EX7: =SUM(EX8:EX9) -> 0 | EY7: =SUM(EP7:EX7) -> 0 | EZ7: =SUM(EZ8:EZ9) -> 0 | FA7: =SUM(FA8:FA9) -> 0 | FB7: =SUM(FB8:FB9) -> 0 | FC7: =SUM(FC8:FC9) -> 0 | FD7: =SUM(FD8:FD9) -> 0 | FE7: =SUM(FE8:FE9) -> 0 | FF7: =SUM(FF8:FF9) -> 0 | FG7: =SUM(FG8:FG9) -> 0 | ... GP7: =SUM(GP8:GP9) -> 0 | GQ7: =SUM(FT7:GP7) -> 0 | GR7: =SUM(GR8:GR9) -> 0 | GS7: =SUM(GS8:GS9) -> 0 | GT7: =SUM(GT8:GT9) -> 0 | GU7: =SUM(GU8:GU9) -> 0 | GV7: =SUM(GV8:GV9) -> 0 | GW7: =SUM(GW8:GW9) -> 0 | GX7: =SUM(GX8:GX9) -> 0 | GY7: =SUM(GY8:GY9) -> 0 | ... MM7: =SUM(MM8:MM9) -> 0
A8: P | B8: 30801 | C8: Parroquia Capital Puerto La Cruz | N8: =SUM(D8:M8) -> 0 | Y8: =SUM(O8:X8) -> 0 | Z8: =IFERROR(O8/D8,0) -> 0 | AA8: =IFERROR(P8/E8,0) -> 0 | AB8: =IFERROR(Q8/F8,0) -> 0 | AC8: =IFERROR(R8/G8,0) -> 0 | AD8: =IFERROR(S8/H8,0) -> 0 | AE8: =IFERROR(T8/I8,0) -> 0 | AF8: =IFERROR(U8/J8,0) -> 0 | AG8: =IFERROR(V8/K8,0) -> 0 | ... AJ8: =IFERROR(Y8/N8,0) -> 0 | AT8: =SUM(AL8:AS8) -> 0 | BU8: =SUM(AU8:BT8) -> 0 | BY8: =SUM(BV8:BX8) -> 0 | DC8: =SUM(BZ8:DB8) -> 0 | DF8: =SUM(DD8:DE8) -> 0 | EJ8: =SUM(EC8:ED8,DX8:DY8,DS8:DT8,DN8:DO8,DI8:DJ8,EI8,) -> 0 | EK8: =SUM(EE8:EH8,DZ8:EB8,DU8:DW8,DP8:DR8,DK8:DM8,DG8:DH8) -> 0 | EO8: =SUM(EL8:EN8) -> 0 | EY8: =SUM(EP8:EX8) -> 0 | FH8: =SUM(EZ8:FG8) -> 0 | FS8: =SUM(FI8:FR8) -> 0 | GQ8: =SUM(FT8:GP8) -> 0 | GS8: =SUM(GR8) -> 0 | HS8: =SUM(GT8:HR8) -> 0 | HV8: =SUM(HT8:HU8) -> 0 | IC8: =SUM(HW8:IB8) -> 0 | IN8: =SUM(ID8:IM8) -> 0 | IO8: =SUM(AT8,BU8,BY8,DC8,DF8,EK8,EO8,EY8,FH8,FS8,GQ8,GS8,HS8,HV8,IC8,IN8,EJ8) -> 0 | JD8: =SUM(IP8,IR8,IT8,IZ8,JB8,IX8,IV8) -> 0 | JE8: =SUM(IQ8,IS8,IU8,JA8,JC8,IY8,IW8) -> 0 | JF8: =SUM(JD8:JE8) -> 0 | JL8: =SUM(JG8:JK8) -> 0 | JO8: =SUM(JM8:JN8) -> 0 | KG8: =SUM(JP8:KF8) -> 0 | KY8: =SUM(KH8:KX8) -> 0
A9: P | B9: 30802 | C9: Parroquia Pozuelos | N9: =SUM(D9:M9) -> 0 | Y9: =SUM(O9:X9) -> 0 | Z9: =IFERROR(O9/D9,0) -> 0 | AA9: =IFERROR(P9/E9,0) -> 0 | AB9: =IFERROR(Q9/F9,0) -> 0 | AC9: =IFERROR(R9/G9,0) -> 0 | AD9: =IFERROR(S9/H9,0) -> 0 | AE9: =IFERROR(T9/I9,0) -> 0 | AF9: =IFERROR(U9/J9,0) -> 0 | AG9: =IFERROR(V9/K9,0) -> 0 | ... AJ9: =IFERROR(Y9/N9,0) -> 0 | AT9: =SUM(AL9:AS9) -> 0 | BU9: =SUM(AU9:BT9) -> 0 | BY9: =SUM(BV9:BX9) -> 0 | DC9: =SUM(BZ9:DB9) -> 0 | DF9: =SUM(DD9:DE9) -> 0 | EJ9: =SUM(EC9:ED9,DX9:DY9,DS9:DT9,DN9:DO9,DI9:DJ9,EI9,) -> 0 | EK9: =SUM(EE9:EH9,DZ9:EB9,DU9:DW9,DP9:DR9,DK9:DM9,DG9:DH9) -> 0 | EO9: =SUM(EL9:EN9) -> 0 | EY9: =SUM(EP9:EX9) -> 0 | FH9: =SUM(EZ9:FG9) -> 0 | FS9: =SUM(FI9:FR9) -> 0 | GQ9: =SUM(FT9:GP9) -> 0 | GS9: =SUM(GR9) -> 0 | HS9: =SUM(GT9:HR9) -> 0 | HV9: =SUM(HT9:HU9) -> 0 | IC9: =SUM(HW9:IB9) -> 0 | IN9: =SUM(ID9:IM9) -> 0 | IO9: =SUM(AT9,BU9,BY9,DC9,DF9,EK9,EO9,EY9,FH9,FS9,GQ9,GS9,HS9,HV9,IC9,IN9,EJ9) -> 0 | JD9: =SUM(IP9,IR9,IT9,IZ9,JB9,IX9,IV9) -> 0 | JE9: =SUM(IQ9,IS9,IU9,JA9,JC9,IY9,IW9) -> 0 | JF9: =SUM(JD9:JE9) -> 0 | JL9: =SUM(JG9:JK9) -> 0 | JO9: =SUM(JM9:JN9) -> 0 | KG9: =SUM(JP9:KF9) -> 0 | KY9: =SUM(KH9:KX9) -> 0
A10: M | B10: 30600 | C10: Municipio Guanta | D10: =SUM(D11:D12) -> 0 | E10: =SUM(E11:E12) -> 0 | F10: =SUM(F11:F12) -> 0 | G10: =SUM(G11:G12) -> 0 | H10: =SUM(H11:H12) -> 0 | I10: =SUM(I11:I12) -> 0 | J10: =SUM(J11:J12) -> 0 | K10: =SUM(K11:K12) -> 0 | ... Y10: =SUM(Y11:Y12) -> 0 | Z10: =IFERROR(O10/D10,0) -> 0 | AA10: =IFERROR(P10/E10,0) -> 0 | AB10: =IFERROR(Q10/F10,0) -> 0 | AC10: =IFERROR(R10/G10,0) -> 0 | AD10: =IFERROR(S10/H10,0) -> 0 | AE10: =IFERROR(T10/I10,0) -> 0 | AF10: =IFERROR(U10/J10,0) -> 0 | AG10: =IFERROR(V10/K10,0) -> 0 | ... AJ10: =IFERROR(Y10/N10,0) -> 0 | AK10: =SUM(AK11:AK12) -> 0 | AL10: =SUM(AL11:AL12) -> 0 | AM10: =SUM(AM11:AM12) -> 0 | AN10: =SUM(AN11:AN12) -> 0 | AO10: =SUM(AO11:AO12) -> 0 | AP10: =SUM(AP11:AP12) -> 0 | AQ10: =SUM(AQ11:AQ12) -> 0 | AR10: =SUM(AR11:AR12) -> 0 | ... EX10: =SUM(EX11:EX12) -> 0 | EY10: =SUM(EP10:EX10) -> 0 | EZ10: =SUM(EZ11:EZ12) -> 0 | FA10: =SUM(FA11:FA12) -> 0 | FB10: =SUM(FB11:FB12) -> 0 | FC10: =SUM(FC11:FC12) -> 0 | FD10: =SUM(FD11:FD12) -> 0 | FE10: =SUM(FE11:FE12) -> 0 | FF10: =SUM(FF11:FF12) -> 0 | FG10: =SUM(FG11:FG12) -> 0 | ... GP10: =SUM(GP11:GP12) -> 0 | GQ10: =SUM(FT10:GP10) -> 0 | GR10: =SUM(GR11:GR12) -> 0 | GS10: =SUM(GS11:GS12) -> 0 | GT10: =SUM(GT11:GT12) -> 0 | GU10: =SUM(GU11:GU12) -> 0 | GV10: =SUM(GV11:GV12) -> 0 | GW10: =SUM(GW11:GW12) -> 0 | GX10: =SUM(GX11:GX12) -> 0 | GY10: =SUM(GY11:GY12) -> 0 | ... MM10: =SUM(MM11:MM12) -> 0
A11: P | B11: 30601 | C11: Parroquia Capital Guanta | N11: =SUM(D11:M11) -> 0 | Y11: =SUM(O11:X11) -> 0 | Z11: =IFERROR(O11/D11,0) -> 0 | AA11: =IFERROR(P11/E11,0) -> 0 | AB11: =IFERROR(Q11/F11,0) -> 0 | AC11: =IFERROR(R11/G11,0) -> 0 | AD11: =IFERROR(S11/H11,0) -> 0 | AE11: =IFERROR(T11/I11,0) -> 0 | AF11: =IFERROR(U11/J11,0) -> 0 | AG11: =IFERROR(V11/K11,0) -> 0 | ... AJ11: =IFERROR(Y11/N11,0) -> 0 | AT11: =SUM(AL11:AS11) -> 0 | BU11: =SUM(AU11:BT11) -> 0 | BY11: =SUM(BV11:BX11) -> 0 | DC11: =SUM(BZ11:DB11) -> 0 | DF11: =SUM(DD11:DE11) -> 0 | EJ11: =SUM(EC11:ED11,DX11:DY11,DS11:DT11,DN11:DO11,DI11:DJ11,EI11,) -> 0 | EK11: =SUM(EE11:EH11,DZ11:EB11,DU11:DW11,DP11:DR11,DK11:DM11,DG11:DH11) -> 0 | EO11: =SUM(EL11:EN11) -> 0 | EY11: =SUM(EP11:EX11) -> 0 | FH11: =SUM(EZ11:FG11) -> 0 | FS11: =SUM(FI11:FR11) -> 0 | GQ11: =SUM(FT11:GP11) -> 0 | GS11: =SUM(GR11) -> 0 | HS11: =SUM(GT11:HR11) -> 0 | HV11: =SUM(HT11:HU11) -> 0 | IC11: =SUM(HW11:IB11) -> 0 | IN11: =SUM(ID11:IM11) -> 0 | IO11: =SUM(AT11,BU11,BY11,DC11,DF11,EK11,EO11,EY11,FH11,FS11,GQ11,GS11,HS11,HV11,IC11,IN11,EJ11) -> 0 | JD11: =SUM(IP11,IR11,IT11,IZ11,JB11,IX11,IV11) -> 0 | JE11: =SUM(IQ11,IS11,IU11,JA11,JC11,IY11,IW11) -> 0 | JF11: =SUM(JD11:JE11) -> 0 | JL11: =SUM(JG11:JK11) -> 0 | JO11: =SUM(JM11:JN11) -> 0 | KG11: =SUM(JP11:KF11) -> 0 | KY11: =SUM(KH11:KX11) -> 0
A12: P | B12: 30602 | C12: Parroquia Chorrerón | N12: =SUM(D12:M12) -> 0 | Y12: =SUM(O12:X12) -> 0 | Z12: =IFERROR(O12/D12,0) -> 0 | AA12: =IFERROR(P12/E12,0) -> 0 | AB12: =IFERROR(Q12/F12,0) -> 0 | AC12: =IFERROR(R12/G12,0) -> 0 | AD12: =IFERROR(S12/H12,0) -> 0 | AE12: =IFERROR(T12/I12,0) -> 0 | AF12: =IFERROR(U12/J12,0) -> 0 | AG12: =IFERROR(V12/K12,0) -> 0 | ... AJ12: =IFERROR(Y12/N12,0) -> 0 | AT12: =SUM(AL12:AS12) -> 0 | BU12: =SUM(AU12:BT12) -> 0 | BY12: =SUM(BV12:BX12) -> 0 | DC12: =SUM(BZ12:DB12) -> 0 | DF12: =SUM(DD12:DE12) -> 0 | EJ12: =SUM(EC12:ED12,DX12:DY12,DS12:DT12,DN12:DO12,DI12:DJ12,EI12,) -> 0 | EK12: =SUM(EE12:EH12,DZ12:EB12,DU12:DW12,DP12:DR12,DK12:DM12,DG12:DH12) -> 0 | EO12: =SUM(EL12:EN12) -> 0 | EY12: =SUM(EP12:EX12) -> 0 | FH12: =SUM(EZ12:FG12) -> 0 | FS12: =SUM(FI12:FR12) -> 0 | GQ12: =SUM(FT12:GP12) -> 0 | GS12: =SUM(GR12) -> 0 | HS12: =SUM(GT12:HR12) -> 0 | HV12: =SUM(HT12:HU12) -> 0 | IC12: =SUM(HW12:IB12) -> 0 | IN12: =SUM(ID12:IM12) -> 0 | IO12: =SUM(AT12,BU12,BY12,DC12,DF12,EK12,EO12,EY12,FH12,FS12,GQ12,GS12,HS12,HV12,IC12,IN12,EJ12) -> 0 | JD12: =SUM(IP12,IR12,IT12,IZ12,JB12,IX12,IV12) -> 0 | JE12: =SUM(IQ12,IS12,IU12,JA12,JC12,IY12,IW12) -> 0 | JF12: =SUM(JD12:JE12) -> 0 | JL12: =SUM(JG12:JK12) -> 0 | JO12: =SUM(JM12:JN12) -> 0 | KG12: =SUM(JP12:KF12) -> 0 | KY12: =SUM(KH12:KX12) -> 0
A13: M | B13: 31800 | C13: Municipio Simón Bolívar | D13: =SUM(D14:D19) -> 0 | E13: =SUM(E14:E19) -> 0 | F13: =SUM(F14:F19) -> 0 | G13: =SUM(G14:G19) -> 0 | H13: =SUM(H14:H19) -> 0 | I13: =SUM(I14:I19) -> 0 | J13: =SUM(J14:J19) -> 0 | K13: =SUM(K14:K19) -> 0 | ... Y13: =SUM(Y14:Y19) -> 0 | Z13: =IFERROR(O13/D13,0) -> 0 | AA13: =IFERROR(P13/E13,0) -> 0 | AB13: =IFERROR(Q13/F13,0) -> 0 | AC13: =IFERROR(R13/G13,0) -> 0 | AD13: =IFERROR(S13/H13,0) -> 0 | AE13: =IFERROR(T13/I13,0) -> 0 | AF13: =IFERROR(U13/J13,0) -> 0 | AG13: =IFERROR(V13/K13,0) -> 0 | ... AJ13: =IFERROR(Y13/N13,0) -> 0 | AK13: =SUM(AK14:AK19) -> 0 | AL13: =SUM(AL14:AL19) -> 0 | AM13: =SUM(AM14:AM19) -> 0 | AN13: =SUM(AN14:AN19) -> 0 | AO13: =SUM(AO14:AO19) -> 0 | AP13: =SUM(AP14:AP19) -> 0 | AQ13: =SUM(AQ14:AQ19) -> 0 | AR13: =SUM(AR14:AR19) -> 0 | ... EX13: =SUM(EX14:EX19) -> 0 | EY13: =SUM(EP13:EX13) -> 0 | EZ13: =SUM(EZ14:EZ19) -> 0 | FA13: =SUM(FA14:FA19) -> 0 | FB13: =SUM(FB14:FB19) -> 0 | FC13: =SUM(FC14:FC19) -> 0 | FD13: =SUM(FD14:FD19) -> 0 | FE13: =SUM(FE14:FE19) -> 0 | FF13: =SUM(FF14:FF19) -> 0 | FG13: =SUM(FG14:FG19) -> 0 | ... GP13: =SUM(GP14:GP19) -> 0 | GQ13: =SUM(FT13:GP13) -> 0 | GR13: =SUM(GR14:GR19) -> 0 | GS13: =SUM(GS14:GS19) -> 0 | GT13: =SUM(GT14:GT19) -> 0 | GU13: =SUM(GU14:GU19) -> 0 | GV13: =SUM(GV14:GV19) -> 0 | GW13: =SUM(GW14:GW19) -> 0 | GX13: =SUM(GX14:GX19) -> 0 | GY13: =SUM(GY14:GY19) -> 0 | ... MM13: =SUM(MM14:MM19) -> 0
A14: P | B14: 31801 | C14: Parroquia El Carmen | N14: =SUM(D14:M14) -> 0 | Y14: =SUM(O14:X14) -> 0 | Z14: =IFERROR(O14/D14,0) -> 0 | AA14: =IFERROR(P14/E14,0) -> 0 | AB14: =IFERROR(Q14/F14,0) -> 0 | AC14: =IFERROR(R14/G14,0) -> 0 | AD14: =IFERROR(S14/H14,0) -> 0 | AE14: =IFERROR(T14/I14,0) -> 0 | AF14: =IFERROR(U14/J14,0) -> 0 | AG14: =IFERROR(V14/K14,0) -> 0 | ... AJ14: =IFERROR(Y14/N14,0) -> 0 | AT14: =SUM(AL14:AS14) -> 0 | BU14: =SUM(AU14:BT14) -> 0 | BY14: =SUM(BV14:BX14) -> 0 | DC14: =SUM(BZ14:DB14) -> 0 | DF14: =SUM(DD14:DE14) -> 0 | EJ14: =SUM(EC14:ED14,DX14:DY14,DS14:DT14,DN14:DO14,DI14:DJ14,EI14,) -> 0 | EK14: =SUM(EE14:EH14,DZ14:EB14,DU14:DW14,DP14:DR14,DK14:DM14,DG14:DH14) -> 0 | EO14: =SUM(EL14:EN14) -> 0 | EY14: =SUM(EP14:EX14) -> 0 | FH14: =SUM(EZ14:FG14) -> 0 | FS14: =SUM(FI14:FR14) -> 0 | GQ14: =SUM(FT14:GP14) -> 0 | GS14: =SUM(GR14) -> 0 | HS14: =SUM(GT14:HR14) -> 0 | HV14: =SUM(HT14:HU14) -> 0 | IC14: =SUM(HW14:IB14) -> 0 | IN14: =SUM(ID14:IM14) -> 0 | IO14: =SUM(AT14,BU14,BY14,DC14,DF14,EK14,EO14,EY14,FH14,FS14,GQ14,GS14,HS14,HV14,IC14,IN14,EJ14) -> 0 | JD14: =SUM(IP14,IR14,IT14,IZ14,JB14,IX14,IV14) -> 0 | JE14: =SUM(IQ14,IS14,IU14,JA14,JC14,IY14,IW14) -> 0 | JF14: =SUM(JD14:JE14) -> 0 | JL14: =SUM(JG14:JK14) -> 0 | JO14: =SUM(JM14:JN14) -> 0 | KG14: =SUM(JP14:KF14) -> 0 | KY14: =SUM(KH14:KX14) -> 0
A15: P | B15: 31802 | C15: Parroquia San Cristóbal | N15: =SUM(D15:M15) -> 0 | Y15: =SUM(O15:X15) -> 0 | Z15: =IFERROR(O15/D15,0) -> 0 | AA15: =IFERROR(P15/E15,0) -> 0 | AB15: =IFERROR(Q15/F15,0) -> 0 | AC15: =IFERROR(R15/G15,0) -> 0 | AD15: =IFERROR(S15/H15,0) -> 0 | AE15: =IFERROR(T15/I15,0) -> 0 | AF15: =IFERROR(U15/J15,0) -> 0 | AG15: =IFERROR(V15/K15,0) -> 0 | ... AJ15: =IFERROR(Y15/N15,0) -> 0 | AT15: =SUM(AL15:AS15) -> 0 | BU15: =SUM(AU15:BT15) -> 0 | BY15: =SUM(BV15:BX15) -> 0 | DC15: =SUM(BZ15:DB15) -> 0 | DF15: =SUM(DD15:DE15) -> 0 | EJ15: =SUM(EC15:ED15,DX15:DY15,DS15:DT15,DN15:DO15,DI15:DJ15,EI15,) -> 0 | EK15: =SUM(EE15:EH15,DZ15:EB15,DU15:DW15,DP15:DR15,DK15:DM15,DG15:DH15) -> 0 | EO15: =SUM(EL15:EN15) -> 0 | EY15: =SUM(EP15:EX15) -> 0 | FH15: =SUM(EZ15:FG15) -> 0 | FS15: =SUM(FI15:FR15) -> 0 | GQ15: =SUM(FT15:GP15) -> 0 | GS15: =SUM(GR15) -> 0 | HS15: =SUM(GT15:HR15) -> 0 | HV15: =SUM(HT15:HU15) -> 0 | IC15: =SUM(HW15:IB15) -> 0 | IN15: =SUM(ID15:IM15) -> 0 | IO15: =SUM(AT15,BU15,BY15,DC15,DF15,EK15,EO15,EY15,FH15,FS15,GQ15,GS15,HS15,HV15,IC15,IN15,EJ15) -> 0 | JD15: =SUM(IP15,IR15,IT15,IZ15,JB15,IX15,IV15) -> 0 | JE15: =SUM(IQ15,IS15,IU15,JA15,JC15,IY15,IW15) -> 0 | JF15: =SUM(JD15:JE15) -> 0 | JL15: =SUM(JG15:JK15) -> 0 | JO15: =SUM(JM15:JN15) -> 0 | KG15: =SUM(JP15:KF15) -> 0 | KY15: =SUM(KH15:KX15) -> 0
A16: P | B16: 31803 | C16: Parroquia Bergantín | N16: =SUM(D16:M16) -> 0 | Y16: =SUM(O16:X16) -> 0 | Z16: =IFERROR(O16/D16,0) -> 0 | AA16: =IFERROR(P16/E16,0) -> 0 | AB16: =IFERROR(Q16/F16,0) -> 0 | AC16: =IFERROR(R16/G16,0) -> 0 | AD16: =IFERROR(S16/H16,0) -> 0 | AE16: =IFERROR(T16/I16,0) -> 0 | AF16: =IFERROR(U16/J16,0) -> 0 | AG16: =IFERROR(V16/K16,0) -> 0 | ... AJ16: =IFERROR(Y16/N16,0) -> 0 | AT16: =SUM(AL16:AS16) -> 0 | BU16: =SUM(AU16:BT16) -> 0 | BY16: =SUM(BV16:BX16) -> 0 | DC16: =SUM(BZ16:DB16) -> 0 | DF16: =SUM(DD16:DE16) -> 0 | EJ16: =SUM(EC16:ED16,DX16:DY16,DS16:DT16,DN16:DO16,DI16:DJ16,EI16,) -> 0 | EK16: =SUM(EE16:EH16,DZ16:EB16,DU16:DW16,DP16:DR16,DK16:DM16,DG16:DH16) -> 0 | EO16: =SUM(EL16:EN16) -> 0 | EY16: =SUM(EP16:EX16) -> 0 | FH16: =SUM(EZ16:FG16) -> 0 | FS16: =SUM(FI16:FR16) -> 0 | GQ16: =SUM(FT16:GP16) -> 0 | GS16: =SUM(GR16) -> 0 | HS16: =SUM(GT16:HR16) -> 0 | HV16: =SUM(HT16:HU16) -> 0 | IC16: =SUM(HW16:IB16) -> 0 | IN16: =SUM(ID16:IM16) -> 0 | IO16: =SUM(AT16,BU16,BY16,DC16,DF16,EK16,EO16,EY16,FH16,FS16,GQ16,GS16,HS16,HV16,IC16,IN16,EJ16) -> 0 | JD16: =SUM(IP16,IR16,IT16,IZ16,JB16,IX16,IV16) -> 0 | JE16: =SUM(IQ16,IS16,IU16,JA16,JC16,IY16,IW16) -> 0 | JF16: =SUM(JD16:JE16) -> 0 | JL16: =SUM(JG16:JK16) -> 0 | JO16: =SUM(JM16:JN16) -> 0 | KG16: =SUM(JP16:KF16) -> 0 | KY16: =SUM(KH16:KX16) -> 0
A17: P | B17: 31804 | C17: Parroquia Caigua | N17: =SUM(D17:M17) -> 0 | Y17: =SUM(O17:X17) -> 0 | Z17: =IFERROR(O17/D17,0) -> 0 | AA17: =IFERROR(P17/E17,0) -> 0 | AB17: =IFERROR(Q17/F17,0) -> 0 | AC17: =IFERROR(R17/G17,0) -> 0 | AD17: =IFERROR(S17/H17,0) -> 0 | AE17: =IFERROR(T17/I17,0) -> 0 | AF17: =IFERROR(U17/J17,0) -> 0 | AG17: =IFERROR(V17/K17,0) -> 0 | ... AJ17: =IFERROR(Y17/N17,0) -> 0 | AT17: =SUM(AL17:AS17) -> 0 | BU17: =SUM(AU17:BT17) -> 0 | BY17: =SUM(BV17:BX17) -> 0 | DC17: =SUM(BZ17:DB17) -> 0 | DF17: =SUM(DD17:DE17) -> 0 | EJ17: =SUM(EC17:ED17,DX17:DY17,DS17:DT17,DN17:DO17,DI17:DJ17,EI17,) -> 0 | EK17: =SUM(EE17:EH17,DZ17:EB17,DU17:DW17,DP17:DR17,DK17:DM17,DG17:DH17) -> 0 | EO17: =SUM(EL17:EN17) -> 0 | EY17: =SUM(EP17:EX17) -> 0 | FH17: =SUM(EZ17:FG17) -> 0 | FS17: =SUM(FI17:FR17) -> 0 | GQ17: =SUM(FT17:GP17) -> 0 | GS17: =SUM(GR17) -> 0 | HS17: =SUM(GT17:HR17) -> 0 | HV17: =SUM(HT17:HU17) -> 0 | IC17: =SUM(HW17:IB17) -> 0 | IN17: =SUM(ID17:IM17) -> 0 | IO17: =SUM(AT17,BU17,BY17,DC17,DF17,EK17,EO17,EY17,FH17,FS17,GQ17,GS17,HS17,HV17,IC17,IN17,EJ17) -> 0 | JD17: =SUM(IP17,IR17,IT17,IZ17,JB17,IX17,IV17) -> 0 | JE17: =SUM(IQ17,IS17,IU17,JA17,JC17,IY17,IW17) -> 0 | JF17: =SUM(JD17:JE17) -> 0 | JL17: =SUM(JG17:JK17) -> 0 | JO17: =SUM(JM17:JN17) -> 0 | KG17: =SUM(JP17:KF17) -> 0 | KY17: =SUM(KH17:KX17) -> 0
A18: P | B18: 31805 | C18: Parroquia El Pilar | N18: =SUM(D18:M18) -> 0 | Y18: =SUM(O18:X18) -> 0 | Z18: =IFERROR(O18/D18,0) -> 0 | AA18: =IFERROR(P18/E18,0) -> 0 | AB18: =IFERROR(Q18/F18,0) -> 0 | AC18: =IFERROR(R18/G18,0) -> 0 | AD18: =IFERROR(S18/H18,0) -> 0 | AE18: =IFERROR(T18/I18,0) -> 0 | AF18: =IFERROR(U18/J18,0) -> 0 | AG18: =IFERROR(V18/K18,0) -> 0 | ... AJ18: =IFERROR(Y18/N18,0) -> 0 | AT18: =SUM(AL18:AS18) -> 0 | BU18: =SUM(AU18:BT18) -> 0 | BY18: =SUM(BV18:BX18) -> 0 | DC18: =SUM(BZ18:DB18) -> 0 | DF18: =SUM(DD18:DE18) -> 0 | EJ18: =SUM(EC18:ED18,DX18:DY18,DS18:DT18,DN18:DO18,DI18:DJ18,EI18,) -> 0 | EK18: =SUM(EE18:EH18,DZ18:EB18,DU18:DW18,DP18:DR18,DK18:DM18,DG18:DH18) -> 0 | EO18: =SUM(EL18:EN18) -> 0 | EY18: =SUM(EP18:EX18) -> 0 | FH18: =SUM(EZ18:FG18) -> 0 | FS18: =SUM(FI18:FR18) -> 0 | GQ18: =SUM(FT18:GP18) -> 0 | GS18: =SUM(GR18) -> 0 | HS18: =SUM(GT18:HR18) -> 0 | HV18: =SUM(HT18:HU18) -> 0 | IC18: =SUM(HW18:IB18) -> 0 | IN18: =SUM(ID18:IM18) -> 0 | IO18: =SUM(AT18,BU18,BY18,DC18,DF18,EK18,EO18,EY18,FH18,FS18,GQ18,GS18,HS18,HV18,IC18,IN18,EJ18) -> 0 | JD18: =SUM(IP18,IR18,IT18,IZ18,JB18,IX18,IV18) -> 0 | JE18: =SUM(IQ18,IS18,IU18,JA18,JC18,IY18,IW18) -> 0 | JF18: =SUM(JD18:JE18) -> 0 | JL18: =SUM(JG18:JK18) -> 0 | JO18: =SUM(JM18:JN18) -> 0 | KG18: =SUM(JP18:KF18) -> 0 | KY18: =SUM(KH18:KX18) -> 0
A19: P | B19: 31806 | C19: Parroquia Naricual | N19: =SUM(D19:M19) -> 0 | Y19: =SUM(O19:X19) -> 0 | Z19: =IFERROR(O19/D19,0) -> 0 | AA19: =IFERROR(P19/E19,0) -> 0 | AB19: =IFERROR(Q19/F19,0) -> 0 | AC19: =IFERROR(R19/G19,0) -> 0 | AD19: =IFERROR(S19/H19,0) -> 0 | AE19: =IFERROR(T19/I19,0) -> 0 | AF19: =IFERROR(U19/J19,0) -> 0 | AG19: =IFERROR(V19/K19,0) -> 0 | ... AJ19: =IFERROR(Y19/N19,0) -> 0 | AT19: =SUM(AL19:AS19) -> 0 | BU19: =SUM(AU19:BT19) -> 0 | BY19: =SUM(BV19:BX19) -> 0 | DC19: =SUM(BZ19:DB19) -> 0 | DF19: =SUM(DD19:DE19) -> 0 | EJ19: =SUM(EC19:ED19,DX19:DY19,DS19:DT19,DN19:DO19,DI19:DJ19,EI19,) -> 0 | EK19: =SUM(EE19:EH19,DZ19:EB19,DU19:DW19,DP19:DR19,DK19:DM19,DG19:DH19) -> 0 | EO19: =SUM(EL19:EN19) -> 0 | EY19: =SUM(EP19:EX19) -> 0 | FH19: =SUM(EZ19:FG19) -> 0 | FS19: =SUM(FI19:FR19) -> 0 | GQ19: =SUM(FT19:GP19) -> 0 | GS19: =SUM(GR19) -> 0 | HS19: =SUM(GT19:HR19) -> 0 | HV19: =SUM(HT19:HU19) -> 0 | IC19: =SUM(HW19:IB19) -> 0 | IN19: =SUM(ID19:IM19) -> 0 | IO19: =SUM(AT19,BU19,BY19,DC19,DF19,EK19,EO19,EY19,FH19,FS19,GQ19,GS19,HS19,HV19,IC19,IN19,EJ19) -> 0 | JD19: =SUM(IP19,IR19,IT19,IZ19,JB19,IX19,IV19) -> 0 | JE19: =SUM(IQ19,IS19,IU19,JA19,JC19,IY19,IW19) -> 0 | JF19: =SUM(JD19:JE19) -> 0 | JL19: =SUM(JG19:JK19) -> 0 | JO19: =SUM(JM19:JN19) -> 0 | KG19: =SUM(JP19:KF19) -> 0 | KY19: =SUM(KH19:KX19) -> 0
A20: M | B20: 32100 | C20: Municipio Turistico Diego Bautista Urbaneja | D20: =SUM(D21:D22) -> 0 | E20: =SUM(E21:E22) -> 0 | F20: =SUM(F21:F22) -> 0 | G20: =SUM(G21:G22) -> 0 | H20: =SUM(H21:H22) -> 0 | I20: =SUM(I21:I22) -> 0 | J20: =SUM(J21:J22) -> 0 | K20: =SUM(K21:K22) -> 0 | ... Y20: =SUM(Y21:Y22) -> 0 | Z20: =IFERROR(O20/D20,0) -> 0 | AA20: =IFERROR(P20/E20,0) -> 0 | AB20: =IFERROR(Q20/F20,0) -> 0 | AC20: =IFERROR(R20/G20,0) -> 0 | AD20: =IFERROR(S20/H20,0) -> 0 | AE20: =IFERROR(T20/I20,0) -> 0 | AF20: =IFERROR(U20/J20,0) -> 0 | AG20: =IFERROR(V20/K20,0) -> 0 | ... AJ20: =IFERROR(Y20/N20,0) -> 0 | AK20: =SUM(AK21:AK22) -> 0 | AL20: =SUM(AL21:AL22) -> 0 | AM20: =SUM(AM21:AM22) -> 0 | AN20: =SUM(AN21:AN22) -> 0 | AO20: =SUM(AO21:AO22) -> 0 | AP20: =SUM(AP21:AP22) -> 0 | AQ20: =SUM(AQ21:AQ22) -> 0 | AR20: =SUM(AR21:AR22) -> 0 | ... EX20: =SUM(EX21:EX22) -> 0 | EY20: =SUM(EP20:EX20) -> 0 | EZ20: =SUM(EZ21:EZ22) -> 0 | FA20: =SUM(FA21:FA22) -> 0 | FB20: =SUM(FB21:FB22) -> 0 | FC20: =SUM(FC21:FC22) -> 0 | FD20: =SUM(FD21:FD22) -> 0 | FE20: =SUM(FE21:FE22) -> 0 | FF20: =SUM(FF21:FF22) -> 0 | FG20: =SUM(FG21:FG22) -> 0 | ... GP20: =SUM(GP21:GP22) -> 0 | GQ20: =SUM(FT20:GP20) -> 0 | GR20: =SUM(GR21:GR22) -> 0 | GS20: =SUM(GS21:GS22) -> 0 | GT20: =SUM(GT21:GT22) -> 0 | GU20: =SUM(GU21:GU22) -> 0 | GV20: =SUM(GV21:GV22) -> 0 | GW20: =SUM(GW21:GW22) -> 0 | GX20: =SUM(GX21:GX22) -> 0 | GY20: =SUM(GY21:GY22) -> 0 | ... MM20: =SUM(MM21:MM22) -> 0
A21: P | B21: 32101 | C21: Parroquia Capital Diego Bautista Urbaneja | N21: =SUM(D21:M21) -> 0 | Y21: =SUM(O21:X21) -> 0 | Z21: =IFERROR(O21/D21,0) -> 0 | AA21: =IFERROR(P21/E21,0) -> 0 | AB21: =IFERROR(Q21/F21,0) -> 0 | AC21: =IFERROR(R21/G21,0) -> 0 | AD21: =IFERROR(S21/H21,0) -> 0 | AE21: =IFERROR(T21/I21,0) -> 0 | AF21: =IFERROR(U21/J21,0) -> 0 | AG21: =IFERROR(V21/K21,0) -> 0 | ... AJ21: =IFERROR(Y21/N21,0) -> 0 | AT21: =SUM(AL21:AS21) -> 0 | BU21: =SUM(AU21:BT21) -> 0 | BY21: =SUM(BV21:BX21) -> 0 | DC21: =SUM(BZ21:DB21) -> 0 | DF21: =SUM(DD21:DE21) -> 0 | EJ21: =SUM(EC21:ED21,DX21:DY21,DS21:DT21,DN21:DO21,DI21:DJ21,EI21,) -> 0 | EK21: =SUM(EE21:EH21,DZ21:EB21,DU21:DW21,DP21:DR21,DK21:DM21,DG21:DH21) -> 0 | EO21: =SUM(EL21:EN21) -> 0 | EY21: =SUM(EP21:EX21) -> 0 | FH21: =SUM(EZ21:FG21) -> 0 | FS21: =SUM(FI21:FR21) -> 0 | GQ21: =SUM(FT21:GP21) -> 0 | GS21: =SUM(GR21) -> 0 | HS21: =SUM(GT21:HR21) -> 0 | HV21: =SUM(HT21:HU21) -> 0 | IC21: =SUM(HW21:IB21) -> 0 | IN21: =SUM(ID21:IM21) -> 0 | IO21: =SUM(AT21,BU21,BY21,DC21,DF21,EK21,EO21,EY21,FH21,FS21,GQ21,GS21,HS21,HV21,IC21,IN21,EJ21) -> 0 | JD21: =SUM(IP21,IR21,IT21,IZ21,JB21,IX21,IV21) -> 0 | JE21: =SUM(IQ21,IS21,IU21,JA21,JC21,IY21,IW21) -> 0 | JF21: =SUM(JD21:JE21) -> 0 | JL21: =SUM(JG21:JK21) -> 0 | JO21: =SUM(JM21:JN21) -> 0 | KG21: =SUM(JP21:KF21) -> 0 | KY21: =SUM(KH21:KX21) -> 0
A22: P | B22: 32102 | C22: Parroquia El Morro | N22: =SUM(D22:M22) -> 0 | Y22: =SUM(O22:X22) -> 0 | Z22: =IFERROR(O22/D22,0) -> 0 | AA22: =IFERROR(P22/E22,0) -> 0 | AB22: =IFERROR(Q22/F22,0) -> 0 | AC22: =IFERROR(R22/G22,0) -> 0 | AD22: =IFERROR(S22/H22,0) -> 0 | AE22: =IFERROR(T22/I22,0) -> 0 | AF22: =IFERROR(U22/J22,0) -> 0 | AG22: =IFERROR(V22/K22,0) -> 0 | ... AJ22: =IFERROR(Y22/N22,0) -> 0 | AT22: =SUM(AL22:AS22) -> 0 | BU22: =SUM(AU22:BT22) -> 0 | BY22: =SUM(BV22:BX22) -> 0 | DC22: =SUM(BZ22:DB22) -> 0 | DF22: =SUM(DD22:DE22) -> 0 | EJ22: =SUM(EC22:ED22,DX22:DY22,DS22:DT22,DN22:DO22,DI22:DJ22,EI22,) -> 0 | EK22: =SUM(EE22:EH22,DZ22:EB22,DU22:DW22,DP22:DR22,DK22:DM22,DG22:DH22) -> 0 | EO22: =SUM(EL22:EN22) -> 0 | EY22: =SUM(EP22:EX22) -> 0 | FH22: =SUM(EZ22:FG22) -> 0 | FS22: =SUM(FI22:FR22) -> 0 | GQ22: =SUM(FT22:GP22) -> 0 | GS22: =SUM(GR22) -> 0 | HS22: =SUM(GT22:HR22) -> 0 | HV22: =SUM(HT22:HU22) -> 0 | IC22: =SUM(HW22:IB22) -> 0 | IN22: =SUM(ID22:IM22) -> 0 | IO22: =SUM(AT22,BU22,BY22,DC22,DF22,EK22,EO22,EY22,FH22,FS22,GQ22,GS22,HS22,HV22,IC22,IN22,EJ22) -> 0 | JD22: =SUM(IP22,IR22,IT22,IZ22,JB22,IX22,IV22) -> 0 | JE22: =SUM(IQ22,IS22,IU22,JA22,JC22,IY22,IW22) -> 0 | JF22: =SUM(JD22:JE22) -> 0 | JL22: =SUM(JG22:JK22) -> 0 | JO22: =SUM(JM22:JN22) -> 0 | KG22: =SUM(JP22:KF22) -> 0 | KY22: =SUM(KH22:KX22) -> 0
A23: M | B23: 31100 | C23: Municipio Libertad | D23: =SUM(D24:D26) -> 0 | E23: =SUM(E24:E26) -> 0 | F23: =SUM(F24:F26) -> 0 | G23: =SUM(G24:G26) -> 0 | H23: =SUM(H24:H26) -> 0 | I23: =SUM(I24:I26) -> 0 | J23: =SUM(J24:J26) -> 0 | K23: =SUM(K24:K26) -> 0 | ... Y23: =SUM(Y24:Y26) -> 0 | Z23: =IFERROR(O23/D23,0) -> 0 | AA23: =IFERROR(P23/E23,0) -> 0 | AB23: =IFERROR(Q23/F23,0) -> 0 | AC23: =IFERROR(R23/G23,0) -> 0 | AD23: =IFERROR(S23/H23,0) -> 0 | AE23: =IFERROR(T23/I23,0) -> 0 | AF23: =IFERROR(U23/J23,0) -> 0 | AG23: =IFERROR(V23/K23,0) -> 0 | ... AJ23: =IFERROR(Y23/N23,0) -> 0 | AK23: =SUM(AK24:AK26) -> 0 | AL23: =SUM(AL24:AL26) -> 0 | AM23: =SUM(AM24:AM26) -> 0 | AN23: =SUM(AN24:AN26) -> 0 | AO23: =SUM(AO24:AO26) -> 0 | AP23: =SUM(AP24:AP26) -> 0 | AQ23: =SUM(AQ24:AQ26) -> 0 | AR23: =SUM(AR24:AR26) -> 0 | ... EX23: =SUM(EX24:EX26) -> 0 | EY23: =SUM(EP23:EX23) -> 0 | EZ23: =SUM(EZ24:EZ26) -> 0 | FA23: =SUM(FA24:FA26) -> 0 | FB23: =SUM(FB24:FB26) -> 0 | FC23: =SUM(FC24:FC26) -> 0 | FD23: =SUM(FD24:FD26) -> 0 | FE23: =SUM(FE24:FE26) -> 0 | FF23: =SUM(FF24:FF26) -> 0 | FG23: =SUM(FG24:FG26) -> 0 | ... GP23: =SUM(GP24:GP26) -> 0 | GQ23: =SUM(FT23:GP23) -> 0 | GR23: =SUM(GR24:GR26) -> 0 | GS23: =SUM(GS24:GS26) -> 0 | GT23: =SUM(GT24:GT26) -> 0 | GU23: =SUM(GU24:GU26) -> 0 | GV23: =SUM(GV24:GV26) -> 0 | GW23: =SUM(GW24:GW26) -> 0 | GX23: =SUM(GX24:GX26) -> 0 | GY23: =SUM(GY24:GY26) -> 0 | ... MM23: =SUM(MM24:MM26) -> 0
A24: P | B24: 31101 | C24: Parroquia Capital Libertad | N24: =SUM(D24:M24) -> 0 | Y24: =SUM(O24:X24) -> 0 | Z24: =IFERROR(O24/D24,0) -> 0 | AA24: =IFERROR(P24/E24,0) -> 0 | AB24: =IFERROR(Q24/F24,0) -> 0 | AC24: =IFERROR(R24/G24,0) -> 0 | AD24: =IFERROR(S24/H24,0) -> 0 | AE24: =IFERROR(T24/I24,0) -> 0 | AF24: =IFERROR(U24/J24,0) -> 0 | AG24: =IFERROR(V24/K24,0) -> 0 | ... AJ24: =IFERROR(Y24/N24,0) -> 0 | AT24: =SUM(AL24:AS24) -> 0 | BU24: =SUM(AU24:BT24) -> 0 | BY24: =SUM(BV24:BX24) -> 0 | DC24: =SUM(BZ24:DB24) -> 0 | DF24: =SUM(DD24:DE24) -> 0 | EJ24: =SUM(EC24:ED24,DX24:DY24,DS24:DT24,DN24:DO24,DI24:DJ24,EI24,) -> 0 | EK24: =SUM(EE24:EH24,DZ24:EB24,DU24:DW24,DP24:DR24,DK24:DM24,DG24:DH24) -> 0 | EO24: =SUM(EL24:EN24) -> 0 | EY24: =SUM(EP24:EX24) -> 0 | FH24: =SUM(EZ24:FG24) -> 0 | FS24: =SUM(FI24:FR24) -> 0 | GQ24: =SUM(FT24:GP24) -> 0 | GS24: =SUM(GR24) -> 0 | HS24: =SUM(GT24:HR24) -> 0 | HV24: =SUM(HT24:HU24) -> 0 | IC24: =SUM(HW24:IB24) -> 0 | IN24: =SUM(ID24:IM24) -> 0 | IO24: =SUM(AT24,BU24,BY24,DC24,DF24,EK24,EO24,EY24,FH24,FS24,GQ24,GS24,HS24,HV24,IC24,IN24,EJ24) -> 0 | JD24: =SUM(IP24,IR24,IT24,IZ24,JB24,IX24,IV24) -> 0 | JE24: =SUM(IQ24,IS24,IU24,JA24,JC24,IY24,IW24) -> 0 | JF24: =SUM(JD24:JE24) -> 0 | JL24: =SUM(JG24:JK24) -> 0 | JO24: =SUM(JM24:JN24) -> 0 | KG24: =SUM(JP24:KF24) -> 0 | KY24: =SUM(KH24:KX24) -> 0
A25: P | B25: 31102 | C25: Parroquia El Carito | N25: =SUM(D25:M25) -> 0 | Y25: =SUM(O25:X25) -> 0 | Z25: =IFERROR(O25/D25,0) -> 0 | AA25: =IFERROR(P25/E25,0) -> 0 | AB25: =IFERROR(Q25/F25,0) -> 0 | AC25: =IFERROR(R25/G25,0) -> 0 | AD25: =IFERROR(S25/H25,0) -> 0 | AE25: =IFERROR(T25/I25,0) -> 0 | AF25: =IFERROR(U25/J25,0) -> 0 | AG25: =IFERROR(V25/K25,0) -> 0 | ... AJ25: =IFERROR(Y25/N25,0) -> 0 | AT25: =SUM(AL25:AS25) -> 0 | BU25: =SUM(AU25:BT25) -> 0 | BY25: =SUM(BV25:BX25) -> 0 | DC25: =SUM(BZ25:DB25) -> 0 | DF25: =SUM(DD25:DE25) -> 0 | EJ25: =SUM(EC25:ED25,DX25:DY25,DS25:DT25,DN25:DO25,DI25:DJ25,EI25,) -> 0 | EK25: =SUM(EE25:EH25,DZ25:EB25,DU25:DW25,DP25:DR25,DK25:DM25,DG25:DH25) -> 0 | EO25: =SUM(EL25:EN25) -> 0 | EY25: =SUM(EP25:EX25) -> 0 | FH25: =SUM(EZ25:FG25) -> 0 | FS25: =SUM(FI25:FR25) -> 0 | GQ25: =SUM(FT25:GP25) -> 0 | GS25: =SUM(GR25) -> 0 | HS25: =SUM(GT25:HR25) -> 0 | HV25: =SUM(HT25:HU25) -> 0 | IC25: =SUM(HW25:IB25) -> 0 | IN25: =SUM(ID25:IM25) -> 0 | IO25: =SUM(AT25,BU25,BY25,DC25,DF25,EK25,EO25,EY25,FH25,FS25,GQ25,GS25,HS25,HV25,IC25,IN25,EJ25) -> 0 | JD25: =SUM(IP25,IR25,IT25,IZ25,JB25,IX25,IV25) -> 0 | JE25: =SUM(IQ25,IS25,IU25,JA25,JC25,IY25,IW25) -> 0 | JF25: =SUM(JD25:JE25) -> 0 | JL25: =SUM(JG25:JK25) -> 0 | JO25: =SUM(JM25:JN25) -> 0 | KG25: =SUM(JP25:KF25) -> 0 | KY25: =SUM(KH25:KX25) -> 0
A26: P | B26: 31103 | C26: Parroquia Santa Inés | N26: =SUM(D26:M26) -> 0 | Y26: =SUM(O26:X26) -> 0 | Z26: =IFERROR(O26/D26,0) -> 0 | AA26: =IFERROR(P26/E26,0) -> 0 | AB26: =IFERROR(Q26/F26,0) -> 0 | AC26: =IFERROR(R26/G26,0) -> 0 | AD26: =IFERROR(S26/H26,0) -> 0 | AE26: =IFERROR(T26/I26,0) -> 0 | AF26: =IFERROR(U26/J26,0) -> 0 | AG26: =IFERROR(V26/K26,0) -> 0 | ... AJ26: =IFERROR(Y26/N26,0) -> 0 | AT26: =SUM(AL26:AS26) -> 0 | BU26: =SUM(AU26:BT26) -> 0 | BY26: =SUM(BV26:BX26) -> 0 | DC26: =SUM(BZ26:DB26) -> 0 | DF26: =SUM(DD26:DE26) -> 0 | EJ26: =SUM(EC26:ED26,DX26:DY26,DS26:DT26,DN26:DO26,DI26:DJ26,EI26,) -> 0 | EK26: =SUM(EE26:EH26,DZ26:EB26,DU26:DW26,DP26:DR26,DK26:DM26,DG26:DH26) -> 0 | EO26: =SUM(EL26:EN26) -> 0 | EY26: =SUM(EP26:EX26) -> 0 | FH26: =SUM(EZ26:FG26) -> 0 | FS26: =SUM(FI26:FR26) -> 0 | GQ26: =SUM(FT26:GP26) -> 0 | GS26: =SUM(GR26) -> 0 | HS26: =SUM(GT26:HR26) -> 0 | HV26: =SUM(HT26:HU26) -> 0 | IC26: =SUM(HW26:IB26) -> 0 | IN26: =SUM(ID26:IM26) -> 0 | IO26: =SUM(AT26,BU26,BY26,DC26,DF26,EK26,EO26,EY26,FH26,FS26,GQ26,GS26,HS26,HV26,IC26,IN26,EJ26) -> 0 | JD26: =SUM(IP26,IR26,IT26,IZ26,JB26,IX26,IV26) -> 0 | JE26: =SUM(IQ26,IS26,IU26,JA26,JC26,IY26,IW26) -> 0 | JF26: =SUM(JD26:JE26) -> 0 | JL26: =SUM(JG26:JK26) -> 0 | JO26: =SUM(JM26:JN26) -> 0 | KG26: =SUM(JP26:KF26) -> 0 | KY26: =SUM(KH26:KX26) -> 0
A27: M | B27: 31400 | C27: Municipio Píritu | D27: =SUM(D28:D29) -> 0 | E27: =SUM(E28:E29) -> 0 | F27: =SUM(F28:F29) -> 0 | G27: =SUM(G28:G29) -> 0 | H27: =SUM(H28:H29) -> 0 | I27: =SUM(I28:I29) -> 0 | J27: =SUM(J28:J29) -> 0 | K27: =SUM(K28:K29) -> 0 | ... Y27: =SUM(Y28:Y29) -> 0 | Z27: =IFERROR(O27/D27,0) -> 0 | AA27: =IFERROR(P27/E27,0) -> 0 | AB27: =IFERROR(Q27/F27,0) -> 0 | AC27: =IFERROR(R27/G27,0) -> 0 | AD27: =IFERROR(S27/H27,0) -> 0 | AE27: =IFERROR(T27/I27,0) -> 0 | AF27: =IFERROR(U27/J27,0) -> 0 | AG27: =IFERROR(V27/K27,0) -> 0 | ... AJ27: =IFERROR(Y27/N27,0) -> 0 | AK27: =SUM(AK28:AK29) -> 0 | AL27: =SUM(AL28:AL29) -> 0 | AM27: =SUM(AM28:AM29) -> 0 | AN27: =SUM(AN28:AN29) -> 0 | AO27: =SUM(AO28:AO29) -> 0 | AP27: =SUM(AP28:AP29) -> 0 | AQ27: =SUM(AQ28:AQ29) -> 0 | AR27: =SUM(AR28:AR29) -> 0 | ... EX27: =SUM(EX28:EX29) -> 0 | EY27: =SUM(EP27:EX27) -> 0 | EZ27: =SUM(EZ28:EZ29) -> 0 | FA27: =SUM(FA28:FA29) -> 0 | FB27: =SUM(FB28:FB29) -> 0 | FC27: =SUM(FC28:FC29) -> 0 | FD27: =SUM(FD28:FD29) -> 0 | FE27: =SUM(FE28:FE29) -> 0 | FF27: =SUM(FF28:FF29) -> 0 | FG27: =SUM(FG28:FG29) -> 0 | ... GP27: =SUM(GP28:GP29) -> 0 | GQ27: =SUM(FT27:GP27) -> 0 | GR27: =SUM(GR28:GR29) -> 0 | GS27: =SUM(GS28:GS29) -> 0 | GT27: =SUM(GT28:GT29) -> 0 | GU27: =SUM(GU28:GU29) -> 0 | GV27: =SUM(GV28:GV29) -> 0 | GW27: =SUM(GW28:GW29) -> 0 | GX27: =SUM(GX28:GX29) -> 0 | GY27: =SUM(GY28:GY29) -> 0 | ... MM27: =SUM(MM28:MM29) -> 0
A28: P | B28: 31401 | C28: Parroquia Capital Píritu | N28: =SUM(D28:M28) -> 0 | Y28: =SUM(O28:X28) -> 0 | Z28: =IFERROR(O28/D28,0) -> 0 | AA28: =IFERROR(P28/E28,0) -> 0 | AB28: =IFERROR(Q28/F28,0) -> 0 | AC28: =IFERROR(R28/G28,0) -> 0 | AD28: =IFERROR(S28/H28,0) -> 0 | AE28: =IFERROR(T28/I28,0) -> 0 | AF28: =IFERROR(U28/J28,0) -> 0 | AG28: =IFERROR(V28/K28,0) -> 0 | ... AJ28: =IFERROR(Y28/N28,0) -> 0 | AT28: =SUM(AL28:AS28) -> 0 | BU28: =SUM(AU28:BT28) -> 0 | BY28: =SUM(BV28:BX28) -> 0 | DC28: =SUM(BZ28:DB28) -> 0 | DF28: =SUM(DD28:DE28) -> 0 | EJ28: =SUM(EC28:ED28,DX28:DY28,DS28:DT28,DN28:DO28,DI28:DJ28,EI28,) -> 0 | EK28: =SUM(EE28:EH28,DZ28:EB28,DU28:DW28,DP28:DR28,DK28:DM28,DG28:DH28) -> 0 | EO28: =SUM(EL28:EN28) -> 0 | EY28: =SUM(EP28:EX28) -> 0 | FH28: =SUM(EZ28:FG28) -> 0 | FS28: =SUM(FI28:FR28) -> 0 | GQ28: =SUM(FT28:GP28) -> 0 | GS28: =SUM(GR28) -> 0 | HS28: =SUM(GT28:HR28) -> 0 | HV28: =SUM(HT28:HU28) -> 0 | IC28: =SUM(HW28:IB28) -> 0 | IN28: =SUM(ID28:IM28) -> 0 | IO28: =SUM(AT28,BU28,BY28,DC28,DF28,EK28,EO28,EY28,FH28,FS28,GQ28,GS28,HS28,HV28,IC28,IN28,EJ28) -> 0 | JD28: =SUM(IP28,IR28,IT28,IZ28,JB28,IX28,IV28) -> 0 | JE28: =SUM(IQ28,IS28,IU28,JA28,JC28,IY28,IW28) -> 0 | JF28: =SUM(JD28:JE28) -> 0 | JL28: =SUM(JG28:JK28) -> 0 | JO28: =SUM(JM28:JN28) -> 0 | KG28: =SUM(JP28:KF28) -> 0 | KY28: =SUM(KH28:KX28) -> 0
A29: P | B29: 31402 | C29: Parroquia San Francisco | N29: =SUM(D29:M29) -> 0 | Y29: =SUM(O29:X29) -> 0 | Z29: =IFERROR(O29/D29,0) -> 0 | AA29: =IFERROR(P29/E29,0) -> 0 | AB29: =IFERROR(Q29/F29,0) -> 0 | AC29: =IFERROR(R29/G29,0) -> 0 | AD29: =IFERROR(S29/H29,0) -> 0 | AE29: =IFERROR(T29/I29,0) -> 0 | AF29: =IFERROR(U29/J29,0) -> 0 | AG29: =IFERROR(V29/K29,0) -> 0 | ... AJ29: =IFERROR(Y29/N29,0) -> 0 | AT29: =SUM(AL29:AS29) -> 0 | BU29: =SUM(AU29:BT29) -> 0 | BY29: =SUM(BV29:BX29) -> 0 | DC29: =SUM(BZ29:DB29) -> 0 | DF29: =SUM(DD29:DE29) -> 0 | EJ29: =SUM(EC29:ED29,DX29:DY29,DS29:DT29,DN29:DO29,DI29:DJ29,EI29,) -> 0 | EK29: =SUM(EE29:EH29,DZ29:EB29,DU29:DW29,DP29:DR29,DK29:DM29,DG29:DH29) -> 0 | EO29: =SUM(EL29:EN29) -> 0 | EY29: =SUM(EP29:EX29) -> 0 | FH29: =SUM(EZ29:FG29) -> 0 | FS29: =SUM(FI29:FR29) -> 0 | GQ29: =SUM(FT29:GP29) -> 0 | GS29: =SUM(GR29) -> 0 | HS29: =SUM(GT29:HR29) -> 0 | HV29: =SUM(HT29:HU29) -> 0 | IC29: =SUM(HW29:IB29) -> 0 | IN29: =SUM(ID29:IM29) -> 0 | IO29: =SUM(AT29,BU29,BY29,DC29,DF29,EK29,EO29,EY29,FH29,FS29,GQ29,GS29,HS29,HV29,IC29,IN29,EJ29) -> 0 | JD29: =SUM(IP29,IR29,IT29,IZ29,JB29,IX29,IV29) -> 0 | JE29: =SUM(IQ29,IS29,IU29,JA29,JC29,IY29,IW29) -> 0 | JF29: =SUM(JD29:JE29) -> 0 | JL29: =SUM(JG29:JK29) -> 0 | JO29: =SUM(JM29:JN29) -> 0 | KG29: =SUM(JP29:KF29) -> 0 | KY29: =SUM(KH29:KX29) -> 0
A30: M | B30: 31200 | C30: Municipio Manuel Ezequiel Bruzual | D30: =SUM(D31:D33) -> 0 | E30: =SUM(E31:E33) -> 0 | F30: =SUM(F31:F33) -> 0 | G30: =SUM(G31:G33) -> 0 | H30: =SUM(H31:H33) -> 0 | I30: =SUM(I31:I33) -> 0 | J30: =SUM(J31:J33) -> 0 | K30: =SUM(K31:K33) -> 0 | ... Y30: =SUM(Y31:Y33) -> 0 | Z30: =IFERROR(O30/D30,0) -> 0 | AA30: =IFERROR(P30/E30,0) -> 0 | AB30: =IFERROR(Q30/F30,0) -> 0 | AC30: =IFERROR(R30/G30,0) -> 0 | AD30: =IFERROR(S30/H30,0) -> 0 | AE30: =IFERROR(T30/I30,0) -> 0 | AF30: =IFERROR(U30/J30,0) -> 0 | AG30: =IFERROR(V30/K30,0) -> 0 | ... AJ30: =IFERROR(Y30/N30,0) -> 0 | AK30: =SUM(AK31:AK33) -> 0 | AL30: =SUM(AL31:AL33) -> 0 | AM30: =SUM(AM31:AM33) -> 0 | AN30: =SUM(AN31:AN33) -> 0 | AO30: =SUM(AO31:AO33) -> 0 | AP30: =SUM(AP31:AP33) -> 0 | AQ30: =SUM(AQ31:AQ33) -> 0 | AR30: =SUM(AR31:AR33) -> 0 | ... EX30: =SUM(EX31:EX33) -> 0 | EY30: =SUM(EP30:EX30) -> 0 | EZ30: =SUM(EZ31:EZ33) -> 0 | FA30: =SUM(FA31:FA33) -> 0 | FB30: =SUM(FB31:FB33) -> 0 | FC30: =SUM(FC31:FC33) -> 0 | FD30: =SUM(FD31:FD33) -> 0 | FE30: =SUM(FE31:FE33) -> 0 | FF30: =SUM(FF31:FF33) -> 0 | FG30: =SUM(FG31:FG33) -> 0 | ... GP30: =SUM(GP31:GP33) -> 0 | GQ30: =SUM(FT30:GP30) -> 0 | GR30: =SUM(GR31:GR33) -> 0 | GS30: =SUM(GS31:GS33) -> 0 | GT30: =SUM(GT31:GT33) -> 0 | GU30: =SUM(GU31:GU33) -> 0 | GV30: =SUM(GV31:GV33) -> 0 | GW30: =SUM(GW31:GW33) -> 0 | GX30: =SUM(GX31:GX33) -> 0 | GY30: =SUM(GY31:GY33) -> 0 | ... MM30: =SUM(MM31:MM33) -> 0
A31: P | B31: 31201 | C31: Parroquia Capital Manuel Ezequiel Bruzual | N31: =SUM(D31:M31) -> 0 | Y31: =SUM(O31:X31) -> 0 | Z31: =IFERROR(O31/D31,0) -> 0 | AA31: =IFERROR(P31/E31,0) -> 0 | AB31: =IFERROR(Q31/F31,0) -> 0 | AC31: =IFERROR(R31/G31,0) -> 0 | AD31: =IFERROR(S31/H31,0) -> 0 | AE31: =IFERROR(T31/I31,0) -> 0 | AF31: =IFERROR(U31/J31,0) -> 0 | AG31: =IFERROR(V31/K31,0) -> 0 | ... AJ31: =IFERROR(Y31/N31,0) -> 0 | AT31: =SUM(AL31:AS31) -> 0 | BU31: =SUM(AU31:BT31) -> 0 | BY31: =SUM(BV31:BX31) -> 0 | DC31: =SUM(BZ31:DB31) -> 0 | DF31: =SUM(DD31:DE31) -> 0 | EJ31: =SUM(EC31:ED31,DX31:DY31,DS31:DT31,DN31:DO31,DI31:DJ31,EI31,) -> 0 | EK31: =SUM(EE31:EH31,DZ31:EB31,DU31:DW31,DP31:DR31,DK31:DM31,DG31:DH31) -> 0 | EO31: =SUM(EL31:EN31) -> 0 | EY31: =SUM(EP31:EX31) -> 0 | FH31: =SUM(EZ31:FG31) -> 0 | FS31: =SUM(FI31:FR31) -> 0 | GQ31: =SUM(FT31:GP31) -> 0 | GS31: =SUM(GR31) -> 0 | HS31: =SUM(GT31:HR31) -> 0 | HV31: =SUM(HT31:HU31) -> 0 | IC31: =SUM(HW31:IB31) -> 0 | IN31: =SUM(ID31:IM31) -> 0 | IO31: =SUM(AT31,BU31,BY31,DC31,DF31,EK31,EO31,EY31,FH31,FS31,GQ31,GS31,HS31,HV31,IC31,IN31,EJ31) -> 0 | JD31: =SUM(IP31,IR31,IT31,IZ31,JB31,IX31,IV31) -> 0 | JE31: =SUM(IQ31,IS31,IU31,JA31,JC31,IY31,IW31) -> 0 | JF31: =SUM(JD31:JE31) -> 0 | JL31: =SUM(JG31:JK31) -> 0 | JO31: =SUM(JM31:JN31) -> 0 | KG31: =SUM(JP31:KF31) -> 0 | KY31: =SUM(KH31:KX31) -> 0
A32: P | B32: 31202 | C32: Parroquia Guanape | N32: =SUM(D32:M32) -> 0 | Y32: =SUM(O32:X32) -> 0 | Z32: =IFERROR(O32/D32,0) -> 0 | AA32: =IFERROR(P32/E32,0) -> 0 | AB32: =IFERROR(Q32/F32,0) -> 0 | AC32: =IFERROR(R32/G32,0) -> 0 | AD32: =IFERROR(S32/H32,0) -> 0 | AE32: =IFERROR(T32/I32,0) -> 0 | AF32: =IFERROR(U32/J32,0) -> 0 | AG32: =IFERROR(V32/K32,0) -> 0 | ... AJ32: =IFERROR(Y32/N32,0) -> 0 | AT32: =SUM(AL32:AS32) -> 0 | BU32: =SUM(AU32:BT32) -> 0 | BY32: =SUM(BV32:BX32) -> 0 | DC32: =SUM(BZ32:DB32) -> 0 | DF32: =SUM(DD32:DE32) -> 0 | EJ32: =SUM(EC32:ED32,DX32:DY32,DS32:DT32,DN32:DO32,DI32:DJ32,EI32,) -> 0 | EK32: =SUM(EE32:EH32,DZ32:EB32,DU32:DW32,DP32:DR32,DK32:DM32,DG32:DH32) -> 0 | EO32: =SUM(EL32:EN32) -> 0 | EY32: =SUM(EP32:EX32) -> 0 | FH32: =SUM(EZ32:FG32) -> 0 | FS32: =SUM(FI32:FR32) -> 0 | GQ32: =SUM(FT32:GP32) -> 0 | GS32: =SUM(GR32) -> 0 | HS32: =SUM(GT32:HR32) -> 0 | HV32: =SUM(HT32:HU32) -> 0 | IC32: =SUM(HW32:IB32) -> 0 | IN32: =SUM(ID32:IM32) -> 0 | IO32: =SUM(AT32,BU32,BY32,DC32,DF32,EK32,EO32,EY32,FH32,FS32,GQ32,GS32,HS32,HV32,IC32,IN32,EJ32) -> 0 | JD32: =SUM(IP32,IR32,IT32,IZ32,JB32,IX32,IV32) -> 0 | JE32: =SUM(IQ32,IS32,IU32,JA32,JC32,IY32,IW32) -> 0 | JF32: =SUM(JD32:JE32) -> 0 | JL32: =SUM(JG32:JK32) -> 0 | JO32: =SUM(JM32:JN32) -> 0 | KG32: =SUM(JP32:KF32) -> 0 | KY32: =SUM(KH32:KX32) -> 0
A33: P | B33: 31203 | C33: Parroquia Sabana de Uchire | N33: =SUM(D33:M33) -> 0 | Y33: =SUM(O33:X33) -> 0 | Z33: =IFERROR(O33/D33,0) -> 0 | AA33: =IFERROR(P33/E33,0) -> 0 | AB33: =IFERROR(Q33/F33,0) -> 0 | AC33: =IFERROR(R33/G33,0) -> 0 | AD33: =IFERROR(S33/H33,0) -> 0 | AE33: =IFERROR(T33/I33,0) -> 0 | AF33: =IFERROR(U33/J33,0) -> 0 | AG33: =IFERROR(V33/K33,0) -> 0 | ... AJ33: =IFERROR(Y33/N33,0) -> 0 | AT33: =SUM(AL33:AS33) -> 0 | BU33: =SUM(AU33:BT33) -> 0 | BY33: =SUM(BV33:BX33) -> 0 | DC33: =SUM(BZ33:DB33) -> 0 | DF33: =SUM(DD33:DE33) -> 0 | EJ33: =SUM(EC33:ED33,DX33:DY33,DS33:DT33,DN33:DO33,DI33:DJ33,EI33,) -> 0 | EK33: =SUM(EE33:EH33,DZ33:EB33,DU33:DW33,DP33:DR33,DK33:DM33,DG33:DH33) -> 0 | EO33: =SUM(EL33:EN33) -> 0 | EY33: =SUM(EP33:EX33) -> 0 | FH33: =SUM(EZ33:FG33) -> 0 | FS33: =SUM(FI33:FR33) -> 0 | GQ33: =SUM(FT33:GP33) -> 0 | GS33: =SUM(GR33) -> 0 | HS33: =SUM(GT33:HR33) -> 0 | HV33: =SUM(HT33:HU33) -> 0 | IC33: =SUM(HW33:IB33) -> 0 | IN33: =SUM(ID33:IM33) -> 0 | IO33: =SUM(AT33,BU33,BY33,DC33,DF33,EK33,EO33,EY33,FH33,FS33,GQ33,GS33,HS33,HV33,IC33,IN33,EJ33) -> 0 | JD33: =SUM(IP33,IR33,IT33,IZ33,JB33,IX33,IV33) -> 0 | JE33: =SUM(IQ33,IS33,IU33,JA33,JC33,IY33,IW33) -> 0 | JF33: =SUM(JD33:JE33) -> 0 | JL33: =SUM(JG33:JK33) -> 0 | JO33: =SUM(JM33:JN33) -> 0 | KG33: =SUM(JP33:KF33) -> 0 | KY33: =SUM(KH33:KX33) -> 0
A34: M | B34: 30900 | C34: Municipio Juan Manuel Cajigal | D34: =SUM(D35:D36) -> 0 | E34: =SUM(E35:E36) -> 0 | F34: =SUM(F35:F36) -> 0 | G34: =SUM(G35:G36) -> 0 | H34: =SUM(H35:H36) -> 0 | I34: =SUM(I35:I36) -> 0 | J34: =SUM(J35:J36) -> 0 | K34: =SUM(K35:K36) -> 0 | ... Y34: =SUM(Y35:Y36) -> 0 | Z34: =IFERROR(O34/D34,0) -> 0 | AA34: =IFERROR(P34/E34,0) -> 0 | AB34: =IFERROR(Q34/F34,0) -> 0 | AC34: =IFERROR(R34/G34,0) -> 0 | AD34: =IFERROR(S34/H34,0) -> 0 | AE34: =IFERROR(T34/I34,0) -> 0 | AF34: =IFERROR(U34/J34,0) -> 0 | AG34: =IFERROR(V34/K34,0) -> 0 | ... AJ34: =IFERROR(Y34/N34,0) -> 0 | AK34: =SUM(AK35:AK36) -> 0 | AL34: =SUM(AL35:AL36) -> 0 | AM34: =SUM(AM35:AM36) -> 0 | AN34: =SUM(AN35:AN36) -> 0 | AO34: =SUM(AO35:AO36) -> 0 | AP34: =SUM(AP35:AP36) -> 0 | AQ34: =SUM(AQ35:AQ36) -> 0 | AR34: =SUM(AR35:AR36) -> 0 | ... EX34: =SUM(EX35:EX36) -> 0 | EY34: =SUM(EP34:EX34) -> 0 | EZ34: =SUM(EZ35:EZ36) -> 0 | FA34: =SUM(FA35:FA36) -> 0 | FB34: =SUM(FB35:FB36) -> 0 | FC34: =SUM(FC35:FC36) -> 0 | FD34: =SUM(FD35:FD36) -> 0 | FE34: =SUM(FE35:FE36) -> 0 | FF34: =SUM(FF35:FF36) -> 0 | FG34: =SUM(FG35:FG36) -> 0 | ... GP34: =SUM(GP35:GP36) -> 0 | GQ34: =SUM(FT34:GP34) -> 0 | GR34: =SUM(GR35:GR36) -> 0 | GS34: =SUM(GS35:GS36) -> 0 | GT34: =SUM(GT35:GT36) -> 0 | GU34: =SUM(GU35:GU36) -> 0 | GV34: =SUM(GV35:GV36) -> 0 | GW34: =SUM(GW35:GW36) -> 0 | GX34: =SUM(GX35:GX36) -> 0 | GY34: =SUM(GY35:GY36) -> 0 | ... MM34: =SUM(MM35:MM36) -> 0
A35: P | B35: 30901 | C35: Parroquia Capital Juan Manuel Cajigal | N35: =SUM(D35:M35) -> 0 | Y35: =SUM(O35:X35) -> 0 | Z35: =IFERROR(O35/D35,0) -> 0 | AA35: =IFERROR(P35/E35,0) -> 0 | AB35: =IFERROR(Q35/F35,0) -> 0 | AC35: =IFERROR(R35/G35,0) -> 0 | AD35: =IFERROR(S35/H35,0) -> 0 | AE35: =IFERROR(T35/I35,0) -> 0 | AF35: =IFERROR(U35/J35,0) -> 0 | AG35: =IFERROR(V35/K35,0) -> 0 | ... AJ35: =IFERROR(Y35/N35,0) -> 0 | AT35: =SUM(AL35:AS35) -> 0 | BU35: =SUM(AU35:BT35) -> 0 | BY35: =SUM(BV35:BX35) -> 0 | DC35: =SUM(BZ35:DB35) -> 0 | DF35: =SUM(DD35:DE35) -> 0 | EJ35: =SUM(EC35:ED35,DX35:DY35,DS35:DT35,DN35:DO35,DI35:DJ35,EI35,) -> 0 | EK35: =SUM(EE35:EH35,DZ35:EB35,DU35:DW35,DP35:DR35,DK35:DM35,DG35:DH35) -> 0 | EO35: =SUM(EL35:EN35) -> 0 | EY35: =SUM(EP35:EX35) -> 0 | FH35: =SUM(EZ35:FG35) -> 0 | FS35: =SUM(FI35:FR35) -> 0 | GQ35: =SUM(FT35:GP35) -> 0 | GS35: =SUM(GR35) -> 0 | HS35: =SUM(GT35:HR35) -> 0 | HV35: =SUM(HT35:HU35) -> 0 | IC35: =SUM(HW35:IB35) -> 0 | IN35: =SUM(ID35:IM35) -> 0 | IO35: =SUM(AT35,BU35,BY35,DC35,DF35,EK35,EO35,EY35,FH35,FS35,GQ35,GS35,HS35,HV35,IC35,IN35,EJ35) -> 0 | JD35: =SUM(IP35,IR35,IT35,IZ35,JB35,IX35,IV35) -> 0 | JE35: =SUM(IQ35,IS35,IU35,JA35,JC35,IY35,IW35) -> 0 | JF35: =SUM(JD35:JE35) -> 0 | JL35: =SUM(JG35:JK35) -> 0 | JO35: =SUM(JM35:JN35) -> 0 | KG35: =SUM(JP35:KF35) -> 0 | KY35: =SUM(KH35:KX35) -> 0
A36: P | B36: 30902 | C36: Parroquia San Pablo | N36: =SUM(D36:M36) -> 0 | Y36: =SUM(O36:X36) -> 0 | Z36: =IFERROR(O36/D36,0) -> 0 | AA36: =IFERROR(P36/E36,0) -> 0 | AB36: =IFERROR(Q36/F36,0) -> 0 | AC36: =IFERROR(R36/G36,0) -> 0 | AD36: =IFERROR(S36/H36,0) -> 0 | AE36: =IFERROR(T36/I36,0) -> 0 | AF36: =IFERROR(U36/J36,0) -> 0 | AG36: =IFERROR(V36/K36,0) -> 0 | ... AJ36: =IFERROR(Y36/N36,0) -> 0 | AT36: =SUM(AL36:AS36) -> 0 | BU36: =SUM(AU36:BT36) -> 0 | BY36: =SUM(BV36:BX36) -> 0 | DC36: =SUM(BZ36:DB36) -> 0 | DF36: =SUM(DD36:DE36) -> 0 | EJ36: =SUM(EC36:ED36,DX36:DY36,DS36:DT36,DN36:DO36,DI36:DJ36,EI36,) -> 0 | EK36: =SUM(EE36:EH36,DZ36:EB36,DU36:DW36,DP36:DR36,DK36:DM36,DG36:DH36) -> 0 | EO36: =SUM(EL36:EN36) -> 0 | EY36: =SUM(EP36:EX36) -> 0 | FH36: =SUM(EZ36:FG36) -> 0 | FS36: =SUM(FI36:FR36) -> 0 | GQ36: =SUM(FT36:GP36) -> 0 | GS36: =SUM(GR36) -> 0 | HS36: =SUM(GT36:HR36) -> 0 | HV36: =SUM(HT36:HU36) -> 0 | IC36: =SUM(HW36:IB36) -> 0 | IN36: =SUM(ID36:IM36) -> 0 | IO36: =SUM(AT36,BU36,BY36,DC36,DF36,EK36,EO36,EY36,FH36,FS36,GQ36,GS36,HS36,HV36,IC36,IN36,EJ36) -> 0 | JD36: =SUM(IP36,IR36,IT36,IZ36,JB36,IX36,IV36) -> 0 | JE36: =SUM(IQ36,IS36,IU36,JA36,JC36,IY36,IW36) -> 0 | JF36: =SUM(JD36:JE36) -> 0 | JL36: =SUM(JG36:JK36) -> 0 | JO36: =SUM(JM36:JN36) -> 0 | KG36: =SUM(JP36:KF36) -> 0 | KY36: =SUM(KH36:KX36) -> 0
A37: M | B37: 30400 | C37: Municipio Francisco del Carmen Carvajal | D37: =SUM(D38:D39) -> 0 | E37: =SUM(E38:E39) -> 0 | F37: =SUM(F38:F39) -> 0 | G37: =SUM(G38:G39) -> 0 | H37: =SUM(H38:H39) -> 0 | I37: =SUM(I38:I39) -> 0 | J37: =SUM(J38:J39) -> 0 | K37: =SUM(K38:K39) -> 0 | ... Y37: =SUM(Y38:Y39) -> 0 | Z37: =IFERROR(O37/D37,0) -> 0 | AA37: =IFERROR(P37/E37,0) -> 0 | AB37: =IFERROR(Q37/F37,0) -> 0 | AC37: =IFERROR(R37/G37,0) -> 0 | AD37: =IFERROR(S37/H37,0) -> 0 | AE37: =IFERROR(T37/I37,0) -> 0 | AF37: =IFERROR(U37/J37,0) -> 0 | AG37: =IFERROR(V37/K37,0) -> 0 | ... AJ37: =IFERROR(Y37/N37,0) -> 0 | AK37: =SUM(AK38:AK39) -> 0 | AL37: =SUM(AL38:AL39) -> 0 | AM37: =SUM(AM38:AM39) -> 0 | AN37: =SUM(AN38:AN39) -> 0 | AO37: =SUM(AO38:AO39) -> 0 | AP37: =SUM(AP38:AP39) -> 0 | AQ37: =SUM(AQ38:AQ39) -> 0 | AR37: =SUM(AR38:AR39) -> 0 | ... EX37: =SUM(EX38:EX39) -> 0 | EY37: =SUM(EP37:EX37) -> 0 | EZ37: =SUM(EZ38:EZ39) -> 0 | FA37: =SUM(FA38:FA39) -> 0 | FB37: =SUM(FB38:FB39) -> 0 | FC37: =SUM(FC38:FC39) -> 0 | FD37: =SUM(FD38:FD39) -> 0 | FE37: =SUM(FE38:FE39) -> 0 | FF37: =SUM(FF38:FF39) -> 0 | FG37: =SUM(FG38:FG39) -> 0 | ... GP37: =SUM(GP38:GP39) -> 0 | GQ37: =SUM(FT37:GP37) -> 0 | GR37: =SUM(GR38:GR39) -> 0 | GS37: =SUM(GS38:GS39) -> 0 | GT37: =SUM(GT38:GT39) -> 0 | GU37: =SUM(GU38:GU39) -> 0 | GV37: =SUM(GV38:GV39) -> 0 | GW37: =SUM(GW38:GW39) -> 0 | GX37: =SUM(GX38:GX39) -> 0 | GY37: =SUM(GY38:GY39) -> 0 | ... MM37: =SUM(MM38:MM39) -> 0
A38: P | B38: 30401 | C38: Parroquia Capital Francisco del Carmen Carvajal | N38: =SUM(D38:M38) -> 0 | Y38: =SUM(O38:X38) -> 0 | Z38: =IFERROR(O38/D38,0) -> 0 | AA38: =IFERROR(P38/E38,0) -> 0 | AB38: =IFERROR(Q38/F38,0) -> 0 | AC38: =IFERROR(R38/G38,0) -> 0 | AD38: =IFERROR(S38/H38,0) -> 0 | AE38: =IFERROR(T38/I38,0) -> 0 | AF38: =IFERROR(U38/J38,0) -> 0 | AG38: =IFERROR(V38/K38,0) -> 0 | ... AJ38: =IFERROR(Y38/N38,0) -> 0 | AT38: =SUM(AL38:AS38) -> 0 | BU38: =SUM(AU38:BT38) -> 0 | BY38: =SUM(BV38:BX38) -> 0 | DC38: =SUM(BZ38:DB38) -> 0 | DF38: =SUM(DD38:DE38) -> 0 | EJ38: =SUM(EC38:ED38,DX38:DY38,DS38:DT38,DN38:DO38,DI38:DJ38,EI38,) -> 0 | EK38: =SUM(EE38:EH38,DZ38:EB38,DU38:DW38,DP38:DR38,DK38:DM38,DG38:DH38) -> 0 | EO38: =SUM(EL38:EN38) -> 0 | EY38: =SUM(EP38:EX38) -> 0 | FH38: =SUM(EZ38:FG38) -> 0 | FS38: =SUM(FI38:FR38) -> 0 | GQ38: =SUM(FT38:GP38) -> 0 | GS38: =SUM(GR38) -> 0 | HS38: =SUM(GT38:HR38) -> 0 | HV38: =SUM(HT38:HU38) -> 0 | IC38: =SUM(HW38:IB38) -> 0 | IN38: =SUM(ID38:IM38) -> 0 | IO38: =SUM(AT38,BU38,BY38,DC38,DF38,EK38,EO38,EY38,FH38,FS38,GQ38,GS38,HS38,HV38,IC38,IN38,EJ38) -> 0 | JD38: =SUM(IP38,IR38,IT38,IZ38,JB38,IX38,IV38) -> 0 | JE38: =SUM(IQ38,IS38,IU38,JA38,JC38,IY38,IW38) -> 0 | JF38: =SUM(JD38:JE38) -> 0 | JL38: =SUM(JG38:JK38) -> 0 | JO38: =SUM(JM38:JN38) -> 0 | KG38: =SUM(JP38:KF38) -> 0 | KY38: =SUM(KH38:KX38) -> 0
A39: P | B39: 30402 | C39: Parroquia Santa Bárbara | N39: =SUM(D39:M39) -> 0 | Y39: =SUM(O39:X39) -> 0 | Z39: =IFERROR(O39/D39,0) -> 0 | AA39: =IFERROR(P39/E39,0) -> 0 | AB39: =IFERROR(Q39/F39,0) -> 0 | AC39: =IFERROR(R39/G39,0) -> 0 | AD39: =IFERROR(S39/H39,0) -> 0 | AE39: =IFERROR(T39/I39,0) -> 0 | AF39: =IFERROR(U39/J39,0) -> 0 | AG39: =IFERROR(V39/K39,0) -> 0 | ... AJ39: =IFERROR(Y39/N39,0) -> 0 | AT39: =SUM(AL39:AS39) -> 0 | BU39: =SUM(AU39:BT39) -> 0 | BY39: =SUM(BV39:BX39) -> 0 | DC39: =SUM(BZ39:DB39) -> 0 | DF39: =SUM(DD39:DE39) -> 0 | EJ39: =SUM(EC39:ED39,DX39:DY39,DS39:DT39,DN39:DO39,DI39:DJ39,EI39,) -> 0 | EK39: =SUM(EE39:EH39,DZ39:EB39,DU39:DW39,DP39:DR39,DK39:DM39,DG39:DH39) -> 0 | EO39: =SUM(EL39:EN39) -> 0 | EY39: =SUM(EP39:EX39) -> 0 | FH39: =SUM(EZ39:FG39) -> 0 | FS39: =SUM(FI39:FR39) -> 0 | GQ39: =SUM(FT39:GP39) -> 0 | GS39: =SUM(GR39) -> 0 | HS39: =SUM(GT39:HR39) -> 0 | HV39: =SUM(HT39:HU39) -> 0 | IC39: =SUM(HW39:IB39) -> 0 | IN39: =SUM(ID39:IM39) -> 0 | IO39: =SUM(AT39,BU39,BY39,DC39,DF39,EK39,EO39,EY39,FH39,FS39,GQ39,GS39,HS39,HV39,IC39,IN39,EJ39) -> 0 | JD39: =SUM(IP39,IR39,IT39,IZ39,JB39,IX39,IV39) -> 0 | JE39: =SUM(IQ39,IS39,IU39,JA39,JC39,IY39,IW39) -> 0 | JF39: =SUM(JD39:JE39) -> 0 | JL39: =SUM(JG39:JK39) -> 0 | JO39: =SUM(JM39:JN39) -> 0 | KG39: =SUM(JP39:KF39) -> 0 | KY39: =SUM(KH39:KX39) -> 0
A40: M | B40: 30300 | C40: Municipio Fernando de Peñalver | D40: =SUM(D41:D43) -> 0 | E40: =SUM(E41:E43) -> 0 | F40: =SUM(F41:F43) -> 0 | G40: =SUM(G41:G43) -> 0 | H40: =SUM(H41:H43) -> 0 | I40: =SUM(I41:I43) -> 0 | J40: =SUM(J41:J43) -> 0 | K40: =SUM(K41:K43) -> 0 | ... Y40: =SUM(Y41:Y43) -> 0 | Z40: =IFERROR(O40/D40,0) -> 0 | AA40: =IFERROR(P40/E40,0) -> 0 | AB40: =IFERROR(Q40/F40,0) -> 0 | AC40: =IFERROR(R40/G40,0) -> 0 | AD40: =IFERROR(S40/H40,0) -> 0 | AE40: =IFERROR(T40/I40,0) -> 0 | AF40: =IFERROR(U40/J40,0) -> 0 | AG40: =IFERROR(V40/K40,0) -> 0 | ... AJ40: =IFERROR(Y40/N40,0) -> 0 | AK40: =SUM(AK41:AK43) -> 0 | AL40: =SUM(AL41:AL43) -> 0 | AM40: =SUM(AM41:AM43) -> 0 | AN40: =SUM(AN41:AN43) -> 0 | AO40: =SUM(AO41:AO43) -> 0 | AP40: =SUM(AP41:AP43) -> 0 | AQ40: =SUM(AQ41:AQ43) -> 0 | AR40: =SUM(AR41:AR43) -> 0 | ... EX40: =SUM(EX41:EX43) -> 0 | EY40: =SUM(EP40:EX40) -> 0 | EZ40: =SUM(EZ41:EZ43) -> 0 | FA40: =SUM(FA41:FA43) -> 0 | FB40: =SUM(FB41:FB43) -> 0 | FC40: =SUM(FC41:FC43) -> 0 | FD40: =SUM(FD41:FD43) -> 0 | FE40: =SUM(FE41:FE43) -> 0 | FF40: =SUM(FF41:FF43) -> 0 | FG40: =SUM(FG41:FG43) -> 0 | ... GP40: =SUM(GP41:GP43) -> 0 | GQ40: =SUM(FT40:GP40) -> 0 | GR40: =SUM(GR41:GR43) -> 0 | GS40: =SUM(GS41:GS43) -> 0 | GT40: =SUM(GT41:GT43) -> 0 | GU40: =SUM(GU41:GU43) -> 0 | GV40: =SUM(GV41:GV43) -> 0 | GW40: =SUM(GW41:GW43) -> 0 | GX40: =SUM(GX41:GX43) -> 0 | GY40: =SUM(GY41:GY43) -> 0 | ... MM40: =SUM(MM41:MM43) -> 0
...

Sheet FEBRERO
D1: PUESTOS DE VACUNACIÓN ACTIVOS | O1: PUESTOS DE VACUNACIÓN QUE NOTIFICARON | Z1: PORCENTAJE DE PUESTOS DE VACUNACIÓN NOTIFICANTES | KH1: POBLACIÓN INDÍGENA | KM1: POBLACIÓN INDÍGENA | KR1: POBLACIÓN INDÍGENA
